[2024-05-18T17:39:22.530+0000] {processor.py:161} INFO - Started process (PID=167) to work on /opt/airflow/dags/DE_DP_dag.py
[2024-05-18T17:39:22.532+0000] {processor.py:830} INFO - Processing file /opt/airflow/dags/DE_DP_dag.py for tasks to queue
[2024-05-18T17:39:22.534+0000] {logging_mixin.py:188} INFO - [2024-05-18T17:39:22.533+0000] {dagbag.py:545} INFO - Filling up the DagBag from /opt/airflow/dags/DE_DP_dag.py
[2024-05-18T17:39:24.154+0000] {logging_mixin.py:188} INFO - [2024-05-18T17:39:24.146+0000] {dagbag.py:355} ERROR - Failed to import: /opt/airflow/dags/DE_DP_dag.py
Traceback (most recent call last):
  File "/home/airflow/.local/lib/python3.12/site-packages/airflow/models/dagbag.py", line 351, in parse
    loader.exec_module(new_module)
  File "<frozen importlib._bootstrap_external>", line 995, in exec_module
  File "<frozen importlib._bootstrap>", line 488, in _call_with_frames_removed
  File "/opt/airflow/dags/DE_DP_dag.py", line 130, in <module>
    dag_instance = my_text_classification_dag()
                   ^^^^^^^^^^^^^^^^^^^^^^^^^^^^
  File "/home/airflow/.local/lib/python3.12/site-packages/airflow/models/dag.py", line 4081, in factory
    f(**f_kwargs)
  File "/opt/airflow/dags/DE_DP_dag.py", line 119, in my_text_classification_dag
    train_scoring = train_accuracy_scoring_task(df_trained)
                                                ^^^^^^^^^^
NameError: name 'df_trained' is not defined. Did you mean: 'ds_trained'?
[2024-05-18T17:39:24.158+0000] {processor.py:842} WARNING - No viable dags retrieved from /opt/airflow/dags/DE_DP_dag.py
[2024-05-18T17:39:24.182+0000] {processor.py:183} INFO - Processing /opt/airflow/dags/DE_DP_dag.py took 1.659 seconds
[2024-05-18T17:39:54.365+0000] {processor.py:161} INFO - Started process (PID=214) to work on /opt/airflow/dags/DE_DP_dag.py
[2024-05-18T17:39:54.366+0000] {processor.py:830} INFO - Processing file /opt/airflow/dags/DE_DP_dag.py for tasks to queue
[2024-05-18T17:39:54.368+0000] {logging_mixin.py:188} INFO - [2024-05-18T17:39:54.368+0000] {dagbag.py:545} INFO - Filling up the DagBag from /opt/airflow/dags/DE_DP_dag.py
[2024-05-18T17:39:55.474+0000] {logging_mixin.py:188} INFO - [2024-05-18T17:39:55.466+0000] {dagbag.py:355} ERROR - Failed to import: /opt/airflow/dags/DE_DP_dag.py
Traceback (most recent call last):
  File "/home/airflow/.local/lib/python3.12/site-packages/airflow/models/dagbag.py", line 351, in parse
    loader.exec_module(new_module)
  File "<frozen importlib._bootstrap_external>", line 995, in exec_module
  File "<frozen importlib._bootstrap>", line 488, in _call_with_frames_removed
  File "/opt/airflow/dags/DE_DP_dag.py", line 130, in <module>
    dag_instance = my_text_classification_dag()
                   ^^^^^^^^^^^^^^^^^^^^^^^^^^^^
  File "/home/airflow/.local/lib/python3.12/site-packages/airflow/models/dag.py", line 4081, in factory
    f(**f_kwargs)
  File "/opt/airflow/dags/DE_DP_dag.py", line 119, in my_text_classification_dag
    train_scoring = train_accuracy_scoring_task(df_trained)
                                                ^^^^^^^^^^
NameError: name 'df_trained' is not defined. Did you mean: 'ds_trained'?
[2024-05-18T17:39:55.476+0000] {processor.py:842} WARNING - No viable dags retrieved from /opt/airflow/dags/DE_DP_dag.py
[2024-05-18T17:39:55.500+0000] {processor.py:183} INFO - Processing /opt/airflow/dags/DE_DP_dag.py took 1.141 seconds
[2024-05-18T17:40:25.671+0000] {processor.py:161} INFO - Started process (PID=261) to work on /opt/airflow/dags/DE_DP_dag.py
[2024-05-18T17:40:25.672+0000] {processor.py:830} INFO - Processing file /opt/airflow/dags/DE_DP_dag.py for tasks to queue
[2024-05-18T17:40:25.674+0000] {logging_mixin.py:188} INFO - [2024-05-18T17:40:25.674+0000] {dagbag.py:545} INFO - Filling up the DagBag from /opt/airflow/dags/DE_DP_dag.py
[2024-05-18T17:40:26.827+0000] {logging_mixin.py:188} INFO - [2024-05-18T17:40:26.819+0000] {dagbag.py:355} ERROR - Failed to import: /opt/airflow/dags/DE_DP_dag.py
Traceback (most recent call last):
  File "/home/airflow/.local/lib/python3.12/site-packages/airflow/models/dagbag.py", line 351, in parse
    loader.exec_module(new_module)
  File "<frozen importlib._bootstrap_external>", line 995, in exec_module
  File "<frozen importlib._bootstrap>", line 488, in _call_with_frames_removed
  File "/opt/airflow/dags/DE_DP_dag.py", line 130, in <module>
    dag_instance = my_text_classification_dag()
                   ^^^^^^^^^^^^^^^^^^^^^^^^^^^^
  File "/home/airflow/.local/lib/python3.12/site-packages/airflow/models/dag.py", line 4081, in factory
    f(**f_kwargs)
  File "/opt/airflow/dags/DE_DP_dag.py", line 119, in my_text_classification_dag
    train_scoring = train_accuracy_scoring_task(df_trained)
                                                ^^^^^^^^^^
NameError: name 'df_trained' is not defined. Did you mean: 'ds_trained'?
[2024-05-18T17:40:26.829+0000] {processor.py:842} WARNING - No viable dags retrieved from /opt/airflow/dags/DE_DP_dag.py
[2024-05-18T17:40:26.855+0000] {processor.py:183} INFO - Processing /opt/airflow/dags/DE_DP_dag.py took 1.190 seconds
[2024-05-18T17:40:57.010+0000] {processor.py:161} INFO - Started process (PID=308) to work on /opt/airflow/dags/DE_DP_dag.py
[2024-05-18T17:40:57.011+0000] {processor.py:830} INFO - Processing file /opt/airflow/dags/DE_DP_dag.py for tasks to queue
[2024-05-18T17:40:57.013+0000] {logging_mixin.py:188} INFO - [2024-05-18T17:40:57.012+0000] {dagbag.py:545} INFO - Filling up the DagBag from /opt/airflow/dags/DE_DP_dag.py
[2024-05-18T17:40:58.171+0000] {logging_mixin.py:188} INFO - [2024-05-18T17:40:58.164+0000] {dagbag.py:355} ERROR - Failed to import: /opt/airflow/dags/DE_DP_dag.py
Traceback (most recent call last):
  File "/home/airflow/.local/lib/python3.12/site-packages/airflow/models/dagbag.py", line 351, in parse
    loader.exec_module(new_module)
  File "<frozen importlib._bootstrap_external>", line 995, in exec_module
  File "<frozen importlib._bootstrap>", line 488, in _call_with_frames_removed
  File "/opt/airflow/dags/DE_DP_dag.py", line 130, in <module>
    dag_instance = my_text_classification_dag()
                   ^^^^^^^^^^^^^^^^^^^^^^^^^^^^
  File "/home/airflow/.local/lib/python3.12/site-packages/airflow/models/dag.py", line 4081, in factory
    f(**f_kwargs)
  File "/opt/airflow/dags/DE_DP_dag.py", line 119, in my_text_classification_dag
    train_scoring = train_accuracy_scoring_task(df_trained)
                                                ^^^^^^^^^^
NameError: name 'df_trained' is not defined. Did you mean: 'ds_trained'?
[2024-05-18T17:40:58.173+0000] {processor.py:842} WARNING - No viable dags retrieved from /opt/airflow/dags/DE_DP_dag.py
[2024-05-18T17:40:58.202+0000] {processor.py:183} INFO - Processing /opt/airflow/dags/DE_DP_dag.py took 1.198 seconds
[2024-05-18T17:41:28.363+0000] {processor.py:161} INFO - Started process (PID=355) to work on /opt/airflow/dags/DE_DP_dag.py
[2024-05-18T17:41:28.364+0000] {processor.py:830} INFO - Processing file /opt/airflow/dags/DE_DP_dag.py for tasks to queue
[2024-05-18T17:41:28.366+0000] {logging_mixin.py:188} INFO - [2024-05-18T17:41:28.366+0000] {dagbag.py:545} INFO - Filling up the DagBag from /opt/airflow/dags/DE_DP_dag.py
[2024-05-18T17:41:29.499+0000] {logging_mixin.py:188} INFO - [2024-05-18T17:41:29.492+0000] {dagbag.py:355} ERROR - Failed to import: /opt/airflow/dags/DE_DP_dag.py
Traceback (most recent call last):
  File "/home/airflow/.local/lib/python3.12/site-packages/airflow/models/dagbag.py", line 351, in parse
    loader.exec_module(new_module)
  File "<frozen importlib._bootstrap_external>", line 995, in exec_module
  File "<frozen importlib._bootstrap>", line 488, in _call_with_frames_removed
  File "/opt/airflow/dags/DE_DP_dag.py", line 130, in <module>
    dag_instance = my_text_classification_dag()
                   ^^^^^^^^^^^^^^^^^^^^^^^^^^^^
  File "/home/airflow/.local/lib/python3.12/site-packages/airflow/models/dag.py", line 4081, in factory
    f(**f_kwargs)
  File "/opt/airflow/dags/DE_DP_dag.py", line 119, in my_text_classification_dag
    train_scoring = train_accuracy_scoring_task(df_trained)
                                                ^^^^^^^^^^
NameError: name 'df_trained' is not defined. Did you mean: 'ds_trained'?
[2024-05-18T17:41:29.502+0000] {processor.py:842} WARNING - No viable dags retrieved from /opt/airflow/dags/DE_DP_dag.py
[2024-05-18T17:41:29.526+0000] {processor.py:183} INFO - Processing /opt/airflow/dags/DE_DP_dag.py took 1.169 seconds
[2024-05-18T17:41:59.690+0000] {processor.py:161} INFO - Started process (PID=402) to work on /opt/airflow/dags/DE_DP_dag.py
[2024-05-18T17:41:59.691+0000] {processor.py:830} INFO - Processing file /opt/airflow/dags/DE_DP_dag.py for tasks to queue
[2024-05-18T17:41:59.693+0000] {logging_mixin.py:188} INFO - [2024-05-18T17:41:59.692+0000] {dagbag.py:545} INFO - Filling up the DagBag from /opt/airflow/dags/DE_DP_dag.py
[2024-05-18T17:42:00.807+0000] {logging_mixin.py:188} INFO - [2024-05-18T17:42:00.800+0000] {dagbag.py:355} ERROR - Failed to import: /opt/airflow/dags/DE_DP_dag.py
Traceback (most recent call last):
  File "/home/airflow/.local/lib/python3.12/site-packages/airflow/models/dagbag.py", line 351, in parse
    loader.exec_module(new_module)
  File "<frozen importlib._bootstrap_external>", line 995, in exec_module
  File "<frozen importlib._bootstrap>", line 488, in _call_with_frames_removed
  File "/opt/airflow/dags/DE_DP_dag.py", line 130, in <module>
    dag_instance = my_text_classification_dag()
                   ^^^^^^^^^^^^^^^^^^^^^^^^^^^^
  File "/home/airflow/.local/lib/python3.12/site-packages/airflow/models/dag.py", line 4081, in factory
    f(**f_kwargs)
  File "/opt/airflow/dags/DE_DP_dag.py", line 119, in my_text_classification_dag
    train_scoring = train_accuracy_scoring_task(df_trained)
                                                ^^^^^^^^^^
NameError: name 'df_trained' is not defined. Did you mean: 'ds_trained'?
[2024-05-18T17:42:00.810+0000] {processor.py:842} WARNING - No viable dags retrieved from /opt/airflow/dags/DE_DP_dag.py
[2024-05-18T17:42:00.833+0000] {processor.py:183} INFO - Processing /opt/airflow/dags/DE_DP_dag.py took 1.150 seconds
[2024-05-18T17:42:30.991+0000] {processor.py:161} INFO - Started process (PID=449) to work on /opt/airflow/dags/DE_DP_dag.py
[2024-05-18T17:42:30.992+0000] {processor.py:830} INFO - Processing file /opt/airflow/dags/DE_DP_dag.py for tasks to queue
[2024-05-18T17:42:30.994+0000] {logging_mixin.py:188} INFO - [2024-05-18T17:42:30.994+0000] {dagbag.py:545} INFO - Filling up the DagBag from /opt/airflow/dags/DE_DP_dag.py
[2024-05-18T17:42:32.063+0000] {logging_mixin.py:188} INFO - [2024-05-18T17:42:32.057+0000] {dagbag.py:355} ERROR - Failed to import: /opt/airflow/dags/DE_DP_dag.py
Traceback (most recent call last):
  File "/home/airflow/.local/lib/python3.12/site-packages/airflow/models/dagbag.py", line 351, in parse
    loader.exec_module(new_module)
  File "<frozen importlib._bootstrap_external>", line 995, in exec_module
  File "<frozen importlib._bootstrap>", line 488, in _call_with_frames_removed
  File "/opt/airflow/dags/DE_DP_dag.py", line 130, in <module>
    dag_instance = my_text_classification_dag()
                   ^^^^^^^^^^^^^^^^^^^^^^^^^^^^
  File "/home/airflow/.local/lib/python3.12/site-packages/airflow/models/dag.py", line 4081, in factory
    f(**f_kwargs)
  File "/opt/airflow/dags/DE_DP_dag.py", line 119, in my_text_classification_dag
    train_scoring = train_accuracy_scoring_task(df_trained)
                                                ^^^^^^^^^^
NameError: name 'df_trained' is not defined. Did you mean: 'ds_trained'?
[2024-05-18T17:42:32.065+0000] {processor.py:842} WARNING - No viable dags retrieved from /opt/airflow/dags/DE_DP_dag.py
[2024-05-18T17:42:32.088+0000] {processor.py:183} INFO - Processing /opt/airflow/dags/DE_DP_dag.py took 1.103 seconds
[2024-05-18T17:43:02.141+0000] {processor.py:161} INFO - Started process (PID=496) to work on /opt/airflow/dags/DE_DP_dag.py
[2024-05-18T17:43:02.142+0000] {processor.py:830} INFO - Processing file /opt/airflow/dags/DE_DP_dag.py for tasks to queue
[2024-05-18T17:43:02.144+0000] {logging_mixin.py:188} INFO - [2024-05-18T17:43:02.143+0000] {dagbag.py:545} INFO - Filling up the DagBag from /opt/airflow/dags/DE_DP_dag.py
[2024-05-18T17:43:03.188+0000] {logging_mixin.py:188} INFO - [2024-05-18T17:43:03.181+0000] {dagbag.py:355} ERROR - Failed to import: /opt/airflow/dags/DE_DP_dag.py
Traceback (most recent call last):
  File "/home/airflow/.local/lib/python3.12/site-packages/airflow/models/dagbag.py", line 351, in parse
    loader.exec_module(new_module)
  File "<frozen importlib._bootstrap_external>", line 995, in exec_module
  File "<frozen importlib._bootstrap>", line 488, in _call_with_frames_removed
  File "/opt/airflow/dags/DE_DP_dag.py", line 130, in <module>
    dag_instance = my_text_classification_dag()
                   ^^^^^^^^^^^^^^^^^^^^^^^^^^^^
  File "/home/airflow/.local/lib/python3.12/site-packages/airflow/models/dag.py", line 4081, in factory
    f(**f_kwargs)
  File "/opt/airflow/dags/DE_DP_dag.py", line 119, in my_text_classification_dag
    train_scoring = train_accuracy_scoring_task(df_trained)
                                                ^^^^^^^^^^
NameError: name 'df_trained' is not defined. Did you mean: 'ds_trained'?
[2024-05-18T17:43:03.190+0000] {processor.py:842} WARNING - No viable dags retrieved from /opt/airflow/dags/DE_DP_dag.py
[2024-05-18T17:43:03.213+0000] {processor.py:183} INFO - Processing /opt/airflow/dags/DE_DP_dag.py took 1.081 seconds
[2024-05-18T17:43:33.407+0000] {processor.py:161} INFO - Started process (PID=543) to work on /opt/airflow/dags/DE_DP_dag.py
[2024-05-18T17:43:33.408+0000] {processor.py:830} INFO - Processing file /opt/airflow/dags/DE_DP_dag.py for tasks to queue
[2024-05-18T17:43:33.410+0000] {logging_mixin.py:188} INFO - [2024-05-18T17:43:33.409+0000] {dagbag.py:545} INFO - Filling up the DagBag from /opt/airflow/dags/DE_DP_dag.py
[2024-05-18T17:43:34.483+0000] {logging_mixin.py:188} INFO - [2024-05-18T17:43:34.476+0000] {dagbag.py:355} ERROR - Failed to import: /opt/airflow/dags/DE_DP_dag.py
Traceback (most recent call last):
  File "/home/airflow/.local/lib/python3.12/site-packages/airflow/models/dagbag.py", line 351, in parse
    loader.exec_module(new_module)
  File "<frozen importlib._bootstrap_external>", line 995, in exec_module
  File "<frozen importlib._bootstrap>", line 488, in _call_with_frames_removed
  File "/opt/airflow/dags/DE_DP_dag.py", line 130, in <module>
    dag_instance = my_text_classification_dag()
                   ^^^^^^^^^^^^^^^^^^^^^^^^^^^^
  File "/home/airflow/.local/lib/python3.12/site-packages/airflow/models/dag.py", line 4081, in factory
    f(**f_kwargs)
  File "/opt/airflow/dags/DE_DP_dag.py", line 119, in my_text_classification_dag
    train_scoring = train_accuracy_scoring_task(df_trained)
                                                ^^^^^^^^^^
NameError: name 'df_trained' is not defined. Did you mean: 'ds_trained'?
[2024-05-18T17:43:34.485+0000] {processor.py:842} WARNING - No viable dags retrieved from /opt/airflow/dags/DE_DP_dag.py
[2024-05-18T17:43:34.504+0000] {processor.py:183} INFO - Processing /opt/airflow/dags/DE_DP_dag.py took 1.103 seconds
[2024-05-18T17:44:04.588+0000] {processor.py:161} INFO - Started process (PID=590) to work on /opt/airflow/dags/DE_DP_dag.py
[2024-05-18T17:44:04.590+0000] {processor.py:830} INFO - Processing file /opt/airflow/dags/DE_DP_dag.py for tasks to queue
[2024-05-18T17:44:04.592+0000] {logging_mixin.py:188} INFO - [2024-05-18T17:44:04.591+0000] {dagbag.py:545} INFO - Filling up the DagBag from /opt/airflow/dags/DE_DP_dag.py
[2024-05-18T17:44:05.739+0000] {logging_mixin.py:188} INFO - [2024-05-18T17:44:05.732+0000] {dagbag.py:355} ERROR - Failed to import: /opt/airflow/dags/DE_DP_dag.py
Traceback (most recent call last):
  File "/home/airflow/.local/lib/python3.12/site-packages/airflow/models/dagbag.py", line 351, in parse
    loader.exec_module(new_module)
  File "<frozen importlib._bootstrap_external>", line 995, in exec_module
  File "<frozen importlib._bootstrap>", line 488, in _call_with_frames_removed
  File "/opt/airflow/dags/DE_DP_dag.py", line 130, in <module>
    dag_instance = my_text_classification_dag()
                   ^^^^^^^^^^^^^^^^^^^^^^^^^^^^
  File "/home/airflow/.local/lib/python3.12/site-packages/airflow/models/dag.py", line 4081, in factory
    f(**f_kwargs)
  File "/opt/airflow/dags/DE_DP_dag.py", line 119, in my_text_classification_dag
    train_scoring = train_accuracy_scoring_task(df_trained)
                                                ^^^^^^^^^^
NameError: name 'df_trained' is not defined. Did you mean: 'ds_trained'?
[2024-05-18T17:44:05.742+0000] {processor.py:842} WARNING - No viable dags retrieved from /opt/airflow/dags/DE_DP_dag.py
[2024-05-18T17:44:05.773+0000] {processor.py:183} INFO - Processing /opt/airflow/dags/DE_DP_dag.py took 1.191 seconds
[2024-05-18T17:44:36.082+0000] {processor.py:161} INFO - Started process (PID=637) to work on /opt/airflow/dags/DE_DP_dag.py
[2024-05-18T17:44:36.083+0000] {processor.py:830} INFO - Processing file /opt/airflow/dags/DE_DP_dag.py for tasks to queue
[2024-05-18T17:44:36.086+0000] {logging_mixin.py:188} INFO - [2024-05-18T17:44:36.085+0000] {dagbag.py:545} INFO - Filling up the DagBag from /opt/airflow/dags/DE_DP_dag.py
[2024-05-18T17:44:37.181+0000] {logging_mixin.py:188} INFO - [2024-05-18T17:44:37.174+0000] {dagbag.py:355} ERROR - Failed to import: /opt/airflow/dags/DE_DP_dag.py
Traceback (most recent call last):
  File "/home/airflow/.local/lib/python3.12/site-packages/airflow/models/dagbag.py", line 351, in parse
    loader.exec_module(new_module)
  File "<frozen importlib._bootstrap_external>", line 995, in exec_module
  File "<frozen importlib._bootstrap>", line 488, in _call_with_frames_removed
  File "/opt/airflow/dags/DE_DP_dag.py", line 130, in <module>
    dag_instance = my_text_classification_dag()
                   ^^^^^^^^^^^^^^^^^^^^^^^^^^^^
  File "/home/airflow/.local/lib/python3.12/site-packages/airflow/models/dag.py", line 4081, in factory
    f(**f_kwargs)
  File "/opt/airflow/dags/DE_DP_dag.py", line 119, in my_text_classification_dag
    train_scoring = train_accuracy_scoring_task(df_trained)
                                                ^^^^^^^^^^
NameError: name 'df_trained' is not defined. Did you mean: 'ds_trained'?
[2024-05-18T17:44:37.184+0000] {processor.py:842} WARNING - No viable dags retrieved from /opt/airflow/dags/DE_DP_dag.py
[2024-05-18T17:44:37.208+0000] {processor.py:183} INFO - Processing /opt/airflow/dags/DE_DP_dag.py took 1.133 seconds
[2024-05-18T17:45:07.383+0000] {processor.py:161} INFO - Started process (PID=684) to work on /opt/airflow/dags/DE_DP_dag.py
[2024-05-18T17:45:07.384+0000] {processor.py:830} INFO - Processing file /opt/airflow/dags/DE_DP_dag.py for tasks to queue
[2024-05-18T17:45:07.386+0000] {logging_mixin.py:188} INFO - [2024-05-18T17:45:07.386+0000] {dagbag.py:545} INFO - Filling up the DagBag from /opt/airflow/dags/DE_DP_dag.py
[2024-05-18T17:45:08.479+0000] {logging_mixin.py:188} INFO - [2024-05-18T17:45:08.472+0000] {dagbag.py:355} ERROR - Failed to import: /opt/airflow/dags/DE_DP_dag.py
Traceback (most recent call last):
  File "/home/airflow/.local/lib/python3.12/site-packages/airflow/models/dagbag.py", line 351, in parse
    loader.exec_module(new_module)
  File "<frozen importlib._bootstrap_external>", line 995, in exec_module
  File "<frozen importlib._bootstrap>", line 488, in _call_with_frames_removed
  File "/opt/airflow/dags/DE_DP_dag.py", line 130, in <module>
    dag_instance = my_text_classification_dag()
                   ^^^^^^^^^^^^^^^^^^^^^^^^^^^^
  File "/home/airflow/.local/lib/python3.12/site-packages/airflow/models/dag.py", line 4081, in factory
    f(**f_kwargs)
  File "/opt/airflow/dags/DE_DP_dag.py", line 119, in my_text_classification_dag
    train_scoring = train_accuracy_scoring_task(df_trained)
                                                ^^^^^^^^^^
NameError: name 'df_trained' is not defined. Did you mean: 'ds_trained'?
[2024-05-18T17:45:08.481+0000] {processor.py:842} WARNING - No viable dags retrieved from /opt/airflow/dags/DE_DP_dag.py
[2024-05-18T17:45:08.504+0000] {processor.py:183} INFO - Processing /opt/airflow/dags/DE_DP_dag.py took 1.127 seconds
[2024-05-18T17:45:38.554+0000] {processor.py:161} INFO - Started process (PID=731) to work on /opt/airflow/dags/DE_DP_dag.py
[2024-05-18T17:45:38.556+0000] {processor.py:830} INFO - Processing file /opt/airflow/dags/DE_DP_dag.py for tasks to queue
[2024-05-18T17:45:38.557+0000] {logging_mixin.py:188} INFO - [2024-05-18T17:45:38.557+0000] {dagbag.py:545} INFO - Filling up the DagBag from /opt/airflow/dags/DE_DP_dag.py
[2024-05-18T17:45:39.616+0000] {logging_mixin.py:188} INFO - [2024-05-18T17:45:39.608+0000] {dagbag.py:355} ERROR - Failed to import: /opt/airflow/dags/DE_DP_dag.py
Traceback (most recent call last):
  File "/home/airflow/.local/lib/python3.12/site-packages/airflow/models/dagbag.py", line 351, in parse
    loader.exec_module(new_module)
  File "<frozen importlib._bootstrap_external>", line 995, in exec_module
  File "<frozen importlib._bootstrap>", line 488, in _call_with_frames_removed
  File "/opt/airflow/dags/DE_DP_dag.py", line 130, in <module>
    dag_instance = my_text_classification_dag()
                   ^^^^^^^^^^^^^^^^^^^^^^^^^^^^
  File "/home/airflow/.local/lib/python3.12/site-packages/airflow/models/dag.py", line 4081, in factory
    f(**f_kwargs)
  File "/opt/airflow/dags/DE_DP_dag.py", line 119, in my_text_classification_dag
    train_scoring = train_accuracy_scoring_task(df_trained)
                                                ^^^^^^^^^^
NameError: name 'df_trained' is not defined. Did you mean: 'ds_trained'?
[2024-05-18T17:45:39.619+0000] {processor.py:842} WARNING - No viable dags retrieved from /opt/airflow/dags/DE_DP_dag.py
[2024-05-18T17:45:39.642+0000] {processor.py:183} INFO - Processing /opt/airflow/dags/DE_DP_dag.py took 1.094 seconds
[2024-05-18T17:46:09.835+0000] {processor.py:161} INFO - Started process (PID=778) to work on /opt/airflow/dags/DE_DP_dag.py
[2024-05-18T17:46:09.836+0000] {processor.py:830} INFO - Processing file /opt/airflow/dags/DE_DP_dag.py for tasks to queue
[2024-05-18T17:46:09.838+0000] {logging_mixin.py:188} INFO - [2024-05-18T17:46:09.838+0000] {dagbag.py:545} INFO - Filling up the DagBag from /opt/airflow/dags/DE_DP_dag.py
[2024-05-18T17:46:10.893+0000] {logging_mixin.py:188} INFO - [2024-05-18T17:46:10.886+0000] {dagbag.py:355} ERROR - Failed to import: /opt/airflow/dags/DE_DP_dag.py
Traceback (most recent call last):
  File "/home/airflow/.local/lib/python3.12/site-packages/airflow/models/dagbag.py", line 351, in parse
    loader.exec_module(new_module)
  File "<frozen importlib._bootstrap_external>", line 995, in exec_module
  File "<frozen importlib._bootstrap>", line 488, in _call_with_frames_removed
  File "/opt/airflow/dags/DE_DP_dag.py", line 130, in <module>
    dag_instance = my_text_classification_dag()
                   ^^^^^^^^^^^^^^^^^^^^^^^^^^^^
  File "/home/airflow/.local/lib/python3.12/site-packages/airflow/models/dag.py", line 4081, in factory
    f(**f_kwargs)
  File "/opt/airflow/dags/DE_DP_dag.py", line 119, in my_text_classification_dag
    train_scoring = train_accuracy_scoring_task(df_trained)
                                                ^^^^^^^^^^
NameError: name 'df_trained' is not defined. Did you mean: 'ds_trained'?
[2024-05-18T17:46:10.895+0000] {processor.py:842} WARNING - No viable dags retrieved from /opt/airflow/dags/DE_DP_dag.py
[2024-05-18T17:46:10.919+0000] {processor.py:183} INFO - Processing /opt/airflow/dags/DE_DP_dag.py took 1.089 seconds
[2024-05-18T17:46:41.009+0000] {processor.py:161} INFO - Started process (PID=825) to work on /opt/airflow/dags/DE_DP_dag.py
[2024-05-18T17:46:41.010+0000] {processor.py:830} INFO - Processing file /opt/airflow/dags/DE_DP_dag.py for tasks to queue
[2024-05-18T17:46:41.012+0000] {logging_mixin.py:188} INFO - [2024-05-18T17:46:41.012+0000] {dagbag.py:545} INFO - Filling up the DagBag from /opt/airflow/dags/DE_DP_dag.py
[2024-05-18T17:46:42.106+0000] {logging_mixin.py:188} INFO - [2024-05-18T17:46:42.101+0000] {dagbag.py:355} ERROR - Failed to import: /opt/airflow/dags/DE_DP_dag.py
Traceback (most recent call last):
  File "/home/airflow/.local/lib/python3.12/site-packages/airflow/models/dagbag.py", line 351, in parse
    loader.exec_module(new_module)
  File "<frozen importlib._bootstrap_external>", line 995, in exec_module
  File "<frozen importlib._bootstrap>", line 488, in _call_with_frames_removed
  File "/opt/airflow/dags/DE_DP_dag.py", line 130, in <module>
    dag_instance = my_text_classification_dag()
                   ^^^^^^^^^^^^^^^^^^^^^^^^^^^^
  File "/home/airflow/.local/lib/python3.12/site-packages/airflow/models/dag.py", line 4081, in factory
    f(**f_kwargs)
  File "/opt/airflow/dags/DE_DP_dag.py", line 119, in my_text_classification_dag
    train_scoring = train_accuracy_scoring_task(df_trained)
                                                ^^^^^^^^^^
NameError: name 'df_trained' is not defined. Did you mean: 'ds_trained'?
[2024-05-18T17:46:42.109+0000] {processor.py:842} WARNING - No viable dags retrieved from /opt/airflow/dags/DE_DP_dag.py
[2024-05-18T17:46:42.133+0000] {processor.py:183} INFO - Processing /opt/airflow/dags/DE_DP_dag.py took 1.131 seconds
[2024-05-18T17:47:12.240+0000] {processor.py:161} INFO - Started process (PID=872) to work on /opt/airflow/dags/DE_DP_dag.py
[2024-05-18T17:47:12.241+0000] {processor.py:830} INFO - Processing file /opt/airflow/dags/DE_DP_dag.py for tasks to queue
[2024-05-18T17:47:12.243+0000] {logging_mixin.py:188} INFO - [2024-05-18T17:47:12.242+0000] {dagbag.py:545} INFO - Filling up the DagBag from /opt/airflow/dags/DE_DP_dag.py
[2024-05-18T17:47:13.317+0000] {logging_mixin.py:188} INFO - [2024-05-18T17:47:13.309+0000] {dagbag.py:355} ERROR - Failed to import: /opt/airflow/dags/DE_DP_dag.py
Traceback (most recent call last):
  File "/home/airflow/.local/lib/python3.12/site-packages/airflow/models/dagbag.py", line 351, in parse
    loader.exec_module(new_module)
  File "<frozen importlib._bootstrap_external>", line 995, in exec_module
  File "<frozen importlib._bootstrap>", line 488, in _call_with_frames_removed
  File "/opt/airflow/dags/DE_DP_dag.py", line 130, in <module>
    dag_instance = my_text_classification_dag()
                   ^^^^^^^^^^^^^^^^^^^^^^^^^^^^
  File "/home/airflow/.local/lib/python3.12/site-packages/airflow/models/dag.py", line 4081, in factory
    f(**f_kwargs)
  File "/opt/airflow/dags/DE_DP_dag.py", line 119, in my_text_classification_dag
    train_scoring = train_accuracy_scoring_task(df_trained)
                                                ^^^^^^^^^^
NameError: name 'df_trained' is not defined. Did you mean: 'ds_trained'?
[2024-05-18T17:47:13.319+0000] {processor.py:842} WARNING - No viable dags retrieved from /opt/airflow/dags/DE_DP_dag.py
[2024-05-18T17:47:13.343+0000] {processor.py:183} INFO - Processing /opt/airflow/dags/DE_DP_dag.py took 1.109 seconds
[2024-05-18T17:47:43.445+0000] {processor.py:161} INFO - Started process (PID=919) to work on /opt/airflow/dags/DE_DP_dag.py
[2024-05-18T17:47:43.446+0000] {processor.py:830} INFO - Processing file /opt/airflow/dags/DE_DP_dag.py for tasks to queue
[2024-05-18T17:47:43.448+0000] {logging_mixin.py:188} INFO - [2024-05-18T17:47:43.448+0000] {dagbag.py:545} INFO - Filling up the DagBag from /opt/airflow/dags/DE_DP_dag.py
[2024-05-18T17:47:44.501+0000] {logging_mixin.py:188} INFO - [2024-05-18T17:47:44.494+0000] {dagbag.py:355} ERROR - Failed to import: /opt/airflow/dags/DE_DP_dag.py
Traceback (most recent call last):
  File "/home/airflow/.local/lib/python3.12/site-packages/airflow/models/dagbag.py", line 351, in parse
    loader.exec_module(new_module)
  File "<frozen importlib._bootstrap_external>", line 995, in exec_module
  File "<frozen importlib._bootstrap>", line 488, in _call_with_frames_removed
  File "/opt/airflow/dags/DE_DP_dag.py", line 130, in <module>
    dag_instance = my_text_classification_dag()
                   ^^^^^^^^^^^^^^^^^^^^^^^^^^^^
  File "/home/airflow/.local/lib/python3.12/site-packages/airflow/models/dag.py", line 4081, in factory
    f(**f_kwargs)
  File "/opt/airflow/dags/DE_DP_dag.py", line 119, in my_text_classification_dag
    train_scoring = train_accuracy_scoring_task(df_trained)
                                                ^^^^^^^^^^
NameError: name 'df_trained' is not defined. Did you mean: 'ds_trained'?
[2024-05-18T17:47:44.503+0000] {processor.py:842} WARNING - No viable dags retrieved from /opt/airflow/dags/DE_DP_dag.py
[2024-05-18T17:47:44.527+0000] {processor.py:183} INFO - Processing /opt/airflow/dags/DE_DP_dag.py took 1.087 seconds
[2024-05-18T17:48:14.660+0000] {processor.py:161} INFO - Started process (PID=966) to work on /opt/airflow/dags/DE_DP_dag.py
[2024-05-18T17:48:14.661+0000] {processor.py:830} INFO - Processing file /opt/airflow/dags/DE_DP_dag.py for tasks to queue
[2024-05-18T17:48:14.663+0000] {logging_mixin.py:188} INFO - [2024-05-18T17:48:14.663+0000] {dagbag.py:545} INFO - Filling up the DagBag from /opt/airflow/dags/DE_DP_dag.py
[2024-05-18T17:48:15.718+0000] {logging_mixin.py:188} INFO - [2024-05-18T17:48:15.711+0000] {dagbag.py:355} ERROR - Failed to import: /opt/airflow/dags/DE_DP_dag.py
Traceback (most recent call last):
  File "/home/airflow/.local/lib/python3.12/site-packages/airflow/models/dagbag.py", line 351, in parse
    loader.exec_module(new_module)
  File "<frozen importlib._bootstrap_external>", line 995, in exec_module
  File "<frozen importlib._bootstrap>", line 488, in _call_with_frames_removed
  File "/opt/airflow/dags/DE_DP_dag.py", line 130, in <module>
    dag_instance = my_text_classification_dag()
                   ^^^^^^^^^^^^^^^^^^^^^^^^^^^^
  File "/home/airflow/.local/lib/python3.12/site-packages/airflow/models/dag.py", line 4081, in factory
    f(**f_kwargs)
  File "/opt/airflow/dags/DE_DP_dag.py", line 119, in my_text_classification_dag
    train_scoring = train_accuracy_scoring_task(df_trained)
                                                ^^^^^^^^^^
NameError: name 'df_trained' is not defined. Did you mean: 'ds_trained'?
[2024-05-18T17:48:15.720+0000] {processor.py:842} WARNING - No viable dags retrieved from /opt/airflow/dags/DE_DP_dag.py
[2024-05-18T17:48:15.743+0000] {processor.py:183} INFO - Processing /opt/airflow/dags/DE_DP_dag.py took 1.089 seconds
[2024-05-18T17:48:45.861+0000] {processor.py:161} INFO - Started process (PID=1013) to work on /opt/airflow/dags/DE_DP_dag.py
[2024-05-18T17:48:45.862+0000] {processor.py:830} INFO - Processing file /opt/airflow/dags/DE_DP_dag.py for tasks to queue
[2024-05-18T17:48:45.864+0000] {logging_mixin.py:188} INFO - [2024-05-18T17:48:45.863+0000] {dagbag.py:545} INFO - Filling up the DagBag from /opt/airflow/dags/DE_DP_dag.py
[2024-05-18T17:48:46.918+0000] {logging_mixin.py:188} INFO - [2024-05-18T17:48:46.911+0000] {dagbag.py:355} ERROR - Failed to import: /opt/airflow/dags/DE_DP_dag.py
Traceback (most recent call last):
  File "/home/airflow/.local/lib/python3.12/site-packages/airflow/models/dagbag.py", line 351, in parse
    loader.exec_module(new_module)
  File "<frozen importlib._bootstrap_external>", line 995, in exec_module
  File "<frozen importlib._bootstrap>", line 488, in _call_with_frames_removed
  File "/opt/airflow/dags/DE_DP_dag.py", line 130, in <module>
    dag_instance = my_text_classification_dag()
                   ^^^^^^^^^^^^^^^^^^^^^^^^^^^^
  File "/home/airflow/.local/lib/python3.12/site-packages/airflow/models/dag.py", line 4081, in factory
    f(**f_kwargs)
  File "/opt/airflow/dags/DE_DP_dag.py", line 119, in my_text_classification_dag
    train_scoring = train_accuracy_scoring_task(df_trained)
                                                ^^^^^^^^^^
NameError: name 'df_trained' is not defined. Did you mean: 'ds_trained'?
[2024-05-18T17:48:46.921+0000] {processor.py:842} WARNING - No viable dags retrieved from /opt/airflow/dags/DE_DP_dag.py
[2024-05-18T17:48:46.944+0000] {processor.py:183} INFO - Processing /opt/airflow/dags/DE_DP_dag.py took 1.089 seconds
[2024-05-18T17:49:17.070+0000] {processor.py:161} INFO - Started process (PID=1060) to work on /opt/airflow/dags/DE_DP_dag.py
[2024-05-18T17:49:17.071+0000] {processor.py:830} INFO - Processing file /opt/airflow/dags/DE_DP_dag.py for tasks to queue
[2024-05-18T17:49:17.073+0000] {logging_mixin.py:188} INFO - [2024-05-18T17:49:17.072+0000] {dagbag.py:545} INFO - Filling up the DagBag from /opt/airflow/dags/DE_DP_dag.py
[2024-05-18T17:49:18.132+0000] {logging_mixin.py:188} INFO - [2024-05-18T17:49:18.126+0000] {dagbag.py:355} ERROR - Failed to import: /opt/airflow/dags/DE_DP_dag.py
Traceback (most recent call last):
  File "/home/airflow/.local/lib/python3.12/site-packages/airflow/models/dagbag.py", line 351, in parse
    loader.exec_module(new_module)
  File "<frozen importlib._bootstrap_external>", line 995, in exec_module
  File "<frozen importlib._bootstrap>", line 488, in _call_with_frames_removed
  File "/opt/airflow/dags/DE_DP_dag.py", line 130, in <module>
    dag_instance = my_text_classification_dag()
                   ^^^^^^^^^^^^^^^^^^^^^^^^^^^^
  File "/home/airflow/.local/lib/python3.12/site-packages/airflow/models/dag.py", line 4081, in factory
    f(**f_kwargs)
  File "/opt/airflow/dags/DE_DP_dag.py", line 119, in my_text_classification_dag
    train_scoring = train_accuracy_scoring_task(df_trained)
                                                ^^^^^^^^^^
NameError: name 'df_trained' is not defined. Did you mean: 'ds_trained'?
[2024-05-18T17:49:18.135+0000] {processor.py:842} WARNING - No viable dags retrieved from /opt/airflow/dags/DE_DP_dag.py
[2024-05-18T17:49:18.159+0000] {processor.py:183} INFO - Processing /opt/airflow/dags/DE_DP_dag.py took 1.095 seconds
[2024-05-18T17:49:48.477+0000] {processor.py:161} INFO - Started process (PID=1107) to work on /opt/airflow/dags/DE_DP_dag.py
[2024-05-18T17:49:48.478+0000] {processor.py:830} INFO - Processing file /opt/airflow/dags/DE_DP_dag.py for tasks to queue
[2024-05-18T17:49:48.481+0000] {logging_mixin.py:188} INFO - [2024-05-18T17:49:48.480+0000] {dagbag.py:545} INFO - Filling up the DagBag from /opt/airflow/dags/DE_DP_dag.py
[2024-05-18T17:49:49.724+0000] {logging_mixin.py:188} INFO - [2024-05-18T17:49:49.716+0000] {dagbag.py:355} ERROR - Failed to import: /opt/airflow/dags/DE_DP_dag.py
Traceback (most recent call last):
  File "/home/airflow/.local/lib/python3.12/site-packages/airflow/models/dagbag.py", line 351, in parse
    loader.exec_module(new_module)
  File "<frozen importlib._bootstrap_external>", line 995, in exec_module
  File "<frozen importlib._bootstrap>", line 488, in _call_with_frames_removed
  File "/opt/airflow/dags/DE_DP_dag.py", line 130, in <module>
    dag_instance = my_text_classification_dag()
                   ^^^^^^^^^^^^^^^^^^^^^^^^^^^^
  File "/home/airflow/.local/lib/python3.12/site-packages/airflow/models/dag.py", line 4081, in factory
    f(**f_kwargs)
  File "/opt/airflow/dags/DE_DP_dag.py", line 119, in my_text_classification_dag
    train_scoring = train_accuracy_scoring_task(df_trained)
                                                ^^^^^^^^^^
NameError: name 'df_trained' is not defined. Did you mean: 'ds_trained'?
[2024-05-18T17:49:49.727+0000] {processor.py:842} WARNING - No viable dags retrieved from /opt/airflow/dags/DE_DP_dag.py
[2024-05-18T17:49:49.751+0000] {processor.py:183} INFO - Processing /opt/airflow/dags/DE_DP_dag.py took 1.282 seconds
[2024-05-18T17:50:19.944+0000] {processor.py:161} INFO - Started process (PID=1154) to work on /opt/airflow/dags/DE_DP_dag.py
[2024-05-18T17:50:19.946+0000] {processor.py:830} INFO - Processing file /opt/airflow/dags/DE_DP_dag.py for tasks to queue
[2024-05-18T17:50:19.948+0000] {logging_mixin.py:188} INFO - [2024-05-18T17:50:19.948+0000] {dagbag.py:545} INFO - Filling up the DagBag from /opt/airflow/dags/DE_DP_dag.py
[2024-05-18T17:50:21.218+0000] {logging_mixin.py:188} INFO - [2024-05-18T17:50:21.210+0000] {dagbag.py:355} ERROR - Failed to import: /opt/airflow/dags/DE_DP_dag.py
Traceback (most recent call last):
  File "/home/airflow/.local/lib/python3.12/site-packages/airflow/models/dagbag.py", line 351, in parse
    loader.exec_module(new_module)
  File "<frozen importlib._bootstrap_external>", line 995, in exec_module
  File "<frozen importlib._bootstrap>", line 488, in _call_with_frames_removed
  File "/opt/airflow/dags/DE_DP_dag.py", line 130, in <module>
    dag_instance = my_text_classification_dag()
                   ^^^^^^^^^^^^^^^^^^^^^^^^^^^^
  File "/home/airflow/.local/lib/python3.12/site-packages/airflow/models/dag.py", line 4081, in factory
    f(**f_kwargs)
  File "/opt/airflow/dags/DE_DP_dag.py", line 119, in my_text_classification_dag
    train_scoring = train_accuracy_scoring_task(df_trained)
                                                ^^^^^^^^^^
NameError: name 'df_trained' is not defined. Did you mean: 'ds_trained'?
[2024-05-18T17:50:21.221+0000] {processor.py:842} WARNING - No viable dags retrieved from /opt/airflow/dags/DE_DP_dag.py
[2024-05-18T17:50:21.248+0000] {processor.py:183} INFO - Processing /opt/airflow/dags/DE_DP_dag.py took 1.312 seconds
[2024-05-18T17:50:51.429+0000] {processor.py:161} INFO - Started process (PID=1201) to work on /opt/airflow/dags/DE_DP_dag.py
[2024-05-18T17:50:51.431+0000] {processor.py:830} INFO - Processing file /opt/airflow/dags/DE_DP_dag.py for tasks to queue
[2024-05-18T17:50:51.433+0000] {logging_mixin.py:188} INFO - [2024-05-18T17:50:51.433+0000] {dagbag.py:545} INFO - Filling up the DagBag from /opt/airflow/dags/DE_DP_dag.py
[2024-05-18T17:50:52.601+0000] {logging_mixin.py:188} INFO - [2024-05-18T17:50:52.593+0000] {dagbag.py:355} ERROR - Failed to import: /opt/airflow/dags/DE_DP_dag.py
Traceback (most recent call last):
  File "/home/airflow/.local/lib/python3.12/site-packages/airflow/models/dagbag.py", line 351, in parse
    loader.exec_module(new_module)
  File "<frozen importlib._bootstrap_external>", line 995, in exec_module
  File "<frozen importlib._bootstrap>", line 488, in _call_with_frames_removed
  File "/opt/airflow/dags/DE_DP_dag.py", line 130, in <module>
    dag_instance = my_text_classification_dag()
                   ^^^^^^^^^^^^^^^^^^^^^^^^^^^^
  File "/home/airflow/.local/lib/python3.12/site-packages/airflow/models/dag.py", line 4081, in factory
    f(**f_kwargs)
  File "/opt/airflow/dags/DE_DP_dag.py", line 119, in my_text_classification_dag
    train_scoring = train_accuracy_scoring_task(df_trained)
                                                ^^^^^^^^^^
NameError: name 'df_trained' is not defined. Did you mean: 'ds_trained'?
[2024-05-18T17:50:52.604+0000] {processor.py:842} WARNING - No viable dags retrieved from /opt/airflow/dags/DE_DP_dag.py
[2024-05-18T17:50:52.630+0000] {processor.py:183} INFO - Processing /opt/airflow/dags/DE_DP_dag.py took 1.207 seconds
[2024-05-18T17:51:22.811+0000] {processor.py:161} INFO - Started process (PID=1248) to work on /opt/airflow/dags/DE_DP_dag.py
[2024-05-18T17:51:22.813+0000] {processor.py:830} INFO - Processing file /opt/airflow/dags/DE_DP_dag.py for tasks to queue
[2024-05-18T17:51:22.815+0000] {logging_mixin.py:188} INFO - [2024-05-18T17:51:22.814+0000] {dagbag.py:545} INFO - Filling up the DagBag from /opt/airflow/dags/DE_DP_dag.py
[2024-05-18T17:51:24.011+0000] {logging_mixin.py:188} INFO - [2024-05-18T17:51:24.002+0000] {dagbag.py:355} ERROR - Failed to import: /opt/airflow/dags/DE_DP_dag.py
Traceback (most recent call last):
  File "/home/airflow/.local/lib/python3.12/site-packages/airflow/models/dagbag.py", line 351, in parse
    loader.exec_module(new_module)
  File "<frozen importlib._bootstrap_external>", line 995, in exec_module
  File "<frozen importlib._bootstrap>", line 488, in _call_with_frames_removed
  File "/opt/airflow/dags/DE_DP_dag.py", line 130, in <module>
    dag_instance = my_text_classification_dag()
                   ^^^^^^^^^^^^^^^^^^^^^^^^^^^^
  File "/home/airflow/.local/lib/python3.12/site-packages/airflow/models/dag.py", line 4081, in factory
    f(**f_kwargs)
  File "/opt/airflow/dags/DE_DP_dag.py", line 119, in my_text_classification_dag
    train_scoring = train_accuracy_scoring_task(df_trained)
                                                ^^^^^^^^^^
NameError: name 'df_trained' is not defined. Did you mean: 'ds_trained'?
[2024-05-18T17:51:24.013+0000] {processor.py:842} WARNING - No viable dags retrieved from /opt/airflow/dags/DE_DP_dag.py
[2024-05-18T17:51:24.038+0000] {processor.py:183} INFO - Processing /opt/airflow/dags/DE_DP_dag.py took 1.233 seconds
[2024-05-18T17:51:54.228+0000] {processor.py:161} INFO - Started process (PID=1295) to work on /opt/airflow/dags/DE_DP_dag.py
[2024-05-18T17:51:54.229+0000] {processor.py:830} INFO - Processing file /opt/airflow/dags/DE_DP_dag.py for tasks to queue
[2024-05-18T17:51:54.231+0000] {logging_mixin.py:188} INFO - [2024-05-18T17:51:54.231+0000] {dagbag.py:545} INFO - Filling up the DagBag from /opt/airflow/dags/DE_DP_dag.py
[2024-05-18T17:51:55.386+0000] {logging_mixin.py:188} INFO - [2024-05-18T17:51:55.379+0000] {dagbag.py:355} ERROR - Failed to import: /opt/airflow/dags/DE_DP_dag.py
Traceback (most recent call last):
  File "/home/airflow/.local/lib/python3.12/site-packages/airflow/models/dagbag.py", line 351, in parse
    loader.exec_module(new_module)
  File "<frozen importlib._bootstrap_external>", line 995, in exec_module
  File "<frozen importlib._bootstrap>", line 488, in _call_with_frames_removed
  File "/opt/airflow/dags/DE_DP_dag.py", line 130, in <module>
    dag_instance = my_text_classification_dag()
                   ^^^^^^^^^^^^^^^^^^^^^^^^^^^^
  File "/home/airflow/.local/lib/python3.12/site-packages/airflow/models/dag.py", line 4081, in factory
    f(**f_kwargs)
  File "/opt/airflow/dags/DE_DP_dag.py", line 119, in my_text_classification_dag
    train_scoring = train_accuracy_scoring_task(df_trained)
                                                ^^^^^^^^^^
NameError: name 'df_trained' is not defined. Did you mean: 'ds_trained'?
[2024-05-18T17:51:55.388+0000] {processor.py:842} WARNING - No viable dags retrieved from /opt/airflow/dags/DE_DP_dag.py
[2024-05-18T17:51:55.414+0000] {processor.py:183} INFO - Processing /opt/airflow/dags/DE_DP_dag.py took 1.193 seconds
[2024-05-18T17:52:25.592+0000] {processor.py:161} INFO - Started process (PID=1342) to work on /opt/airflow/dags/DE_DP_dag.py
[2024-05-18T17:52:25.594+0000] {processor.py:830} INFO - Processing file /opt/airflow/dags/DE_DP_dag.py for tasks to queue
[2024-05-18T17:52:25.596+0000] {logging_mixin.py:188} INFO - [2024-05-18T17:52:25.595+0000] {dagbag.py:545} INFO - Filling up the DagBag from /opt/airflow/dags/DE_DP_dag.py
[2024-05-18T17:52:26.753+0000] {logging_mixin.py:188} INFO - [2024-05-18T17:52:26.746+0000] {dagbag.py:355} ERROR - Failed to import: /opt/airflow/dags/DE_DP_dag.py
Traceback (most recent call last):
  File "/home/airflow/.local/lib/python3.12/site-packages/airflow/models/dagbag.py", line 351, in parse
    loader.exec_module(new_module)
  File "<frozen importlib._bootstrap_external>", line 995, in exec_module
  File "<frozen importlib._bootstrap>", line 488, in _call_with_frames_removed
  File "/opt/airflow/dags/DE_DP_dag.py", line 130, in <module>
    dag_instance = my_text_classification_dag()
                   ^^^^^^^^^^^^^^^^^^^^^^^^^^^^
  File "/home/airflow/.local/lib/python3.12/site-packages/airflow/models/dag.py", line 4081, in factory
    f(**f_kwargs)
  File "/opt/airflow/dags/DE_DP_dag.py", line 119, in my_text_classification_dag
    train_scoring = train_accuracy_scoring_task(df_trained)
                                                ^^^^^^^^^^
NameError: name 'df_trained' is not defined. Did you mean: 'ds_trained'?
[2024-05-18T17:52:26.756+0000] {processor.py:842} WARNING - No viable dags retrieved from /opt/airflow/dags/DE_DP_dag.py
[2024-05-18T17:52:26.780+0000] {processor.py:183} INFO - Processing /opt/airflow/dags/DE_DP_dag.py took 1.194 seconds
[2024-05-18T17:52:56.961+0000] {processor.py:161} INFO - Started process (PID=1389) to work on /opt/airflow/dags/DE_DP_dag.py
[2024-05-18T17:52:56.963+0000] {processor.py:830} INFO - Processing file /opt/airflow/dags/DE_DP_dag.py for tasks to queue
[2024-05-18T17:52:56.965+0000] {logging_mixin.py:188} INFO - [2024-05-18T17:52:56.965+0000] {dagbag.py:545} INFO - Filling up the DagBag from /opt/airflow/dags/DE_DP_dag.py
[2024-05-18T17:52:58.093+0000] {logging_mixin.py:188} INFO - [2024-05-18T17:52:58.084+0000] {dagbag.py:355} ERROR - Failed to import: /opt/airflow/dags/DE_DP_dag.py
Traceback (most recent call last):
  File "/home/airflow/.local/lib/python3.12/site-packages/airflow/models/dagbag.py", line 351, in parse
    loader.exec_module(new_module)
  File "<frozen importlib._bootstrap_external>", line 995, in exec_module
  File "<frozen importlib._bootstrap>", line 488, in _call_with_frames_removed
  File "/opt/airflow/dags/DE_DP_dag.py", line 130, in <module>
    dag_instance = my_text_classification_dag()
                   ^^^^^^^^^^^^^^^^^^^^^^^^^^^^
  File "/home/airflow/.local/lib/python3.12/site-packages/airflow/models/dag.py", line 4081, in factory
    f(**f_kwargs)
  File "/opt/airflow/dags/DE_DP_dag.py", line 119, in my_text_classification_dag
    train_scoring = train_accuracy_scoring_task(df_trained)
                                                ^^^^^^^^^^
NameError: name 'df_trained' is not defined. Did you mean: 'ds_trained'?
[2024-05-18T17:52:58.096+0000] {processor.py:842} WARNING - No viable dags retrieved from /opt/airflow/dags/DE_DP_dag.py
[2024-05-18T17:52:58.121+0000] {processor.py:183} INFO - Processing /opt/airflow/dags/DE_DP_dag.py took 1.166 seconds
[2024-05-18T17:53:28.306+0000] {processor.py:161} INFO - Started process (PID=1436) to work on /opt/airflow/dags/DE_DP_dag.py
[2024-05-18T17:53:28.307+0000] {processor.py:830} INFO - Processing file /opt/airflow/dags/DE_DP_dag.py for tasks to queue
[2024-05-18T17:53:28.309+0000] {logging_mixin.py:188} INFO - [2024-05-18T17:53:28.309+0000] {dagbag.py:545} INFO - Filling up the DagBag from /opt/airflow/dags/DE_DP_dag.py
[2024-05-18T17:53:29.476+0000] {logging_mixin.py:188} INFO - [2024-05-18T17:53:29.467+0000] {dagbag.py:355} ERROR - Failed to import: /opt/airflow/dags/DE_DP_dag.py
Traceback (most recent call last):
  File "/home/airflow/.local/lib/python3.12/site-packages/airflow/models/dagbag.py", line 351, in parse
    loader.exec_module(new_module)
  File "<frozen importlib._bootstrap_external>", line 995, in exec_module
  File "<frozen importlib._bootstrap>", line 488, in _call_with_frames_removed
  File "/opt/airflow/dags/DE_DP_dag.py", line 130, in <module>
    dag_instance = my_text_classification_dag()
                   ^^^^^^^^^^^^^^^^^^^^^^^^^^^^
  File "/home/airflow/.local/lib/python3.12/site-packages/airflow/models/dag.py", line 4081, in factory
    f(**f_kwargs)
  File "/opt/airflow/dags/DE_DP_dag.py", line 119, in my_text_classification_dag
    train_scoring = train_accuracy_scoring_task(df_trained)
                                                ^^^^^^^^^^
NameError: name 'df_trained' is not defined. Did you mean: 'ds_trained'?
[2024-05-18T17:53:29.479+0000] {processor.py:842} WARNING - No viable dags retrieved from /opt/airflow/dags/DE_DP_dag.py
[2024-05-18T17:53:29.503+0000] {processor.py:183} INFO - Processing /opt/airflow/dags/DE_DP_dag.py took 1.203 seconds
[2024-05-18T17:53:59.698+0000] {processor.py:161} INFO - Started process (PID=1483) to work on /opt/airflow/dags/DE_DP_dag.py
[2024-05-18T17:53:59.699+0000] {processor.py:830} INFO - Processing file /opt/airflow/dags/DE_DP_dag.py for tasks to queue
[2024-05-18T17:53:59.701+0000] {logging_mixin.py:188} INFO - [2024-05-18T17:53:59.700+0000] {dagbag.py:545} INFO - Filling up the DagBag from /opt/airflow/dags/DE_DP_dag.py
[2024-05-18T17:54:00.900+0000] {logging_mixin.py:188} INFO - [2024-05-18T17:54:00.892+0000] {dagbag.py:355} ERROR - Failed to import: /opt/airflow/dags/DE_DP_dag.py
Traceback (most recent call last):
  File "/home/airflow/.local/lib/python3.12/site-packages/airflow/models/dagbag.py", line 351, in parse
    loader.exec_module(new_module)
  File "<frozen importlib._bootstrap_external>", line 995, in exec_module
  File "<frozen importlib._bootstrap>", line 488, in _call_with_frames_removed
  File "/opt/airflow/dags/DE_DP_dag.py", line 130, in <module>
    dag_instance = my_text_classification_dag()
                   ^^^^^^^^^^^^^^^^^^^^^^^^^^^^
  File "/home/airflow/.local/lib/python3.12/site-packages/airflow/models/dag.py", line 4081, in factory
    f(**f_kwargs)
  File "/opt/airflow/dags/DE_DP_dag.py", line 119, in my_text_classification_dag
    train_scoring = train_accuracy_scoring_task(df_trained)
                                                ^^^^^^^^^^
NameError: name 'df_trained' is not defined. Did you mean: 'ds_trained'?
[2024-05-18T17:54:00.902+0000] {processor.py:842} WARNING - No viable dags retrieved from /opt/airflow/dags/DE_DP_dag.py
[2024-05-18T17:54:00.928+0000] {processor.py:183} INFO - Processing /opt/airflow/dags/DE_DP_dag.py took 1.237 seconds
[2024-05-18T17:54:31.131+0000] {processor.py:161} INFO - Started process (PID=1530) to work on /opt/airflow/dags/DE_DP_dag.py
[2024-05-18T17:54:31.132+0000] {processor.py:830} INFO - Processing file /opt/airflow/dags/DE_DP_dag.py for tasks to queue
[2024-05-18T17:54:31.134+0000] {logging_mixin.py:188} INFO - [2024-05-18T17:54:31.134+0000] {dagbag.py:545} INFO - Filling up the DagBag from /opt/airflow/dags/DE_DP_dag.py
[2024-05-18T17:54:32.260+0000] {logging_mixin.py:188} INFO - [2024-05-18T17:54:32.253+0000] {dagbag.py:355} ERROR - Failed to import: /opt/airflow/dags/DE_DP_dag.py
Traceback (most recent call last):
  File "/home/airflow/.local/lib/python3.12/site-packages/airflow/models/dagbag.py", line 351, in parse
    loader.exec_module(new_module)
  File "<frozen importlib._bootstrap_external>", line 995, in exec_module
  File "<frozen importlib._bootstrap>", line 488, in _call_with_frames_removed
  File "/opt/airflow/dags/DE_DP_dag.py", line 130, in <module>
    dag_instance = my_text_classification_dag()
                   ^^^^^^^^^^^^^^^^^^^^^^^^^^^^
  File "/home/airflow/.local/lib/python3.12/site-packages/airflow/models/dag.py", line 4081, in factory
    f(**f_kwargs)
  File "/opt/airflow/dags/DE_DP_dag.py", line 119, in my_text_classification_dag
    train_scoring = train_accuracy_scoring_task(df_trained)
                                                ^^^^^^^^^^
NameError: name 'df_trained' is not defined. Did you mean: 'ds_trained'?
[2024-05-18T17:54:32.263+0000] {processor.py:842} WARNING - No viable dags retrieved from /opt/airflow/dags/DE_DP_dag.py
[2024-05-18T17:54:32.287+0000] {processor.py:183} INFO - Processing /opt/airflow/dags/DE_DP_dag.py took 1.161 seconds
[2024-05-18T17:55:02.470+0000] {processor.py:161} INFO - Started process (PID=1577) to work on /opt/airflow/dags/DE_DP_dag.py
[2024-05-18T17:55:02.471+0000] {processor.py:830} INFO - Processing file /opt/airflow/dags/DE_DP_dag.py for tasks to queue
[2024-05-18T17:55:02.473+0000] {logging_mixin.py:188} INFO - [2024-05-18T17:55:02.473+0000] {dagbag.py:545} INFO - Filling up the DagBag from /opt/airflow/dags/DE_DP_dag.py
[2024-05-18T17:55:03.611+0000] {logging_mixin.py:188} INFO - [2024-05-18T17:55:03.603+0000] {dagbag.py:355} ERROR - Failed to import: /opt/airflow/dags/DE_DP_dag.py
Traceback (most recent call last):
  File "/home/airflow/.local/lib/python3.12/site-packages/airflow/models/dagbag.py", line 351, in parse
    loader.exec_module(new_module)
  File "<frozen importlib._bootstrap_external>", line 995, in exec_module
  File "<frozen importlib._bootstrap>", line 488, in _call_with_frames_removed
  File "/opt/airflow/dags/DE_DP_dag.py", line 130, in <module>
    dag_instance = my_text_classification_dag()
                   ^^^^^^^^^^^^^^^^^^^^^^^^^^^^
  File "/home/airflow/.local/lib/python3.12/site-packages/airflow/models/dag.py", line 4081, in factory
    f(**f_kwargs)
  File "/opt/airflow/dags/DE_DP_dag.py", line 119, in my_text_classification_dag
    train_scoring = train_accuracy_scoring_task(df_trained)
                                                ^^^^^^^^^^
NameError: name 'df_trained' is not defined. Did you mean: 'ds_trained'?
[2024-05-18T17:55:03.613+0000] {processor.py:842} WARNING - No viable dags retrieved from /opt/airflow/dags/DE_DP_dag.py
[2024-05-18T17:55:03.639+0000] {processor.py:183} INFO - Processing /opt/airflow/dags/DE_DP_dag.py took 1.176 seconds
[2024-05-18T17:55:33.822+0000] {processor.py:161} INFO - Started process (PID=1624) to work on /opt/airflow/dags/DE_DP_dag.py
[2024-05-18T17:55:33.823+0000] {processor.py:830} INFO - Processing file /opt/airflow/dags/DE_DP_dag.py for tasks to queue
[2024-05-18T17:55:33.825+0000] {logging_mixin.py:188} INFO - [2024-05-18T17:55:33.825+0000] {dagbag.py:545} INFO - Filling up the DagBag from /opt/airflow/dags/DE_DP_dag.py
[2024-05-18T17:55:35.016+0000] {logging_mixin.py:188} INFO - [2024-05-18T17:55:35.008+0000] {dagbag.py:355} ERROR - Failed to import: /opt/airflow/dags/DE_DP_dag.py
Traceback (most recent call last):
  File "/home/airflow/.local/lib/python3.12/site-packages/airflow/models/dagbag.py", line 351, in parse
    loader.exec_module(new_module)
  File "<frozen importlib._bootstrap_external>", line 995, in exec_module
  File "<frozen importlib._bootstrap>", line 488, in _call_with_frames_removed
  File "/opt/airflow/dags/DE_DP_dag.py", line 130, in <module>
    dag_instance = my_text_classification_dag()
                   ^^^^^^^^^^^^^^^^^^^^^^^^^^^^
  File "/home/airflow/.local/lib/python3.12/site-packages/airflow/models/dag.py", line 4081, in factory
    f(**f_kwargs)
  File "/opt/airflow/dags/DE_DP_dag.py", line 119, in my_text_classification_dag
    train_scoring = train_accuracy_scoring_task(df_trained)
                                                ^^^^^^^^^^
NameError: name 'df_trained' is not defined. Did you mean: 'ds_trained'?
[2024-05-18T17:55:35.019+0000] {processor.py:842} WARNING - No viable dags retrieved from /opt/airflow/dags/DE_DP_dag.py
[2024-05-18T17:55:35.046+0000] {processor.py:183} INFO - Processing /opt/airflow/dags/DE_DP_dag.py took 1.230 seconds
[2024-05-18T17:56:05.232+0000] {processor.py:161} INFO - Started process (PID=1671) to work on /opt/airflow/dags/DE_DP_dag.py
[2024-05-18T17:56:05.234+0000] {processor.py:830} INFO - Processing file /opt/airflow/dags/DE_DP_dag.py for tasks to queue
[2024-05-18T17:56:05.236+0000] {logging_mixin.py:188} INFO - [2024-05-18T17:56:05.235+0000] {dagbag.py:545} INFO - Filling up the DagBag from /opt/airflow/dags/DE_DP_dag.py
[2024-05-18T17:56:06.382+0000] {logging_mixin.py:188} INFO - [2024-05-18T17:56:06.373+0000] {dagbag.py:355} ERROR - Failed to import: /opt/airflow/dags/DE_DP_dag.py
Traceback (most recent call last):
  File "/home/airflow/.local/lib/python3.12/site-packages/airflow/models/dagbag.py", line 351, in parse
    loader.exec_module(new_module)
  File "<frozen importlib._bootstrap_external>", line 995, in exec_module
  File "<frozen importlib._bootstrap>", line 488, in _call_with_frames_removed
  File "/opt/airflow/dags/DE_DP_dag.py", line 130, in <module>
    dag_instance = my_text_classification_dag()
                   ^^^^^^^^^^^^^^^^^^^^^^^^^^^^
  File "/home/airflow/.local/lib/python3.12/site-packages/airflow/models/dag.py", line 4081, in factory
    f(**f_kwargs)
  File "/opt/airflow/dags/DE_DP_dag.py", line 119, in my_text_classification_dag
    train_scoring = train_accuracy_scoring_task(df_trained)
                                                ^^^^^^^^^^
NameError: name 'df_trained' is not defined. Did you mean: 'ds_trained'?
[2024-05-18T17:56:06.385+0000] {processor.py:842} WARNING - No viable dags retrieved from /opt/airflow/dags/DE_DP_dag.py
[2024-05-18T17:56:06.410+0000] {processor.py:183} INFO - Processing /opt/airflow/dags/DE_DP_dag.py took 1.184 seconds
[2024-05-18T17:56:36.594+0000] {processor.py:161} INFO - Started process (PID=1718) to work on /opt/airflow/dags/DE_DP_dag.py
[2024-05-18T17:56:36.595+0000] {processor.py:830} INFO - Processing file /opt/airflow/dags/DE_DP_dag.py for tasks to queue
[2024-05-18T17:56:36.598+0000] {logging_mixin.py:188} INFO - [2024-05-18T17:56:36.597+0000] {dagbag.py:545} INFO - Filling up the DagBag from /opt/airflow/dags/DE_DP_dag.py
[2024-05-18T17:56:37.738+0000] {logging_mixin.py:188} INFO - [2024-05-18T17:56:37.731+0000] {dagbag.py:355} ERROR - Failed to import: /opt/airflow/dags/DE_DP_dag.py
Traceback (most recent call last):
  File "/home/airflow/.local/lib/python3.12/site-packages/airflow/models/dagbag.py", line 351, in parse
    loader.exec_module(new_module)
  File "<frozen importlib._bootstrap_external>", line 995, in exec_module
  File "<frozen importlib._bootstrap>", line 488, in _call_with_frames_removed
  File "/opt/airflow/dags/DE_DP_dag.py", line 130, in <module>
    dag_instance = my_text_classification_dag()
                   ^^^^^^^^^^^^^^^^^^^^^^^^^^^^
  File "/home/airflow/.local/lib/python3.12/site-packages/airflow/models/dag.py", line 4081, in factory
    f(**f_kwargs)
  File "/opt/airflow/dags/DE_DP_dag.py", line 119, in my_text_classification_dag
    train_scoring = train_accuracy_scoring_task(df_trained)
                                                ^^^^^^^^^^
NameError: name 'df_trained' is not defined. Did you mean: 'ds_trained'?
[2024-05-18T17:56:37.741+0000] {processor.py:842} WARNING - No viable dags retrieved from /opt/airflow/dags/DE_DP_dag.py
[2024-05-18T17:56:37.766+0000] {processor.py:183} INFO - Processing /opt/airflow/dags/DE_DP_dag.py took 1.179 seconds
[2024-05-18T17:57:07.953+0000] {processor.py:161} INFO - Started process (PID=1765) to work on /opt/airflow/dags/DE_DP_dag.py
[2024-05-18T17:57:07.954+0000] {processor.py:830} INFO - Processing file /opt/airflow/dags/DE_DP_dag.py for tasks to queue
[2024-05-18T17:57:07.956+0000] {logging_mixin.py:188} INFO - [2024-05-18T17:57:07.956+0000] {dagbag.py:545} INFO - Filling up the DagBag from /opt/airflow/dags/DE_DP_dag.py
[2024-05-18T17:57:09.142+0000] {logging_mixin.py:188} INFO - [2024-05-18T17:57:09.135+0000] {dagbag.py:355} ERROR - Failed to import: /opt/airflow/dags/DE_DP_dag.py
Traceback (most recent call last):
  File "/home/airflow/.local/lib/python3.12/site-packages/airflow/models/dagbag.py", line 351, in parse
    loader.exec_module(new_module)
  File "<frozen importlib._bootstrap_external>", line 995, in exec_module
  File "<frozen importlib._bootstrap>", line 488, in _call_with_frames_removed
  File "/opt/airflow/dags/DE_DP_dag.py", line 130, in <module>
    dag_instance = my_text_classification_dag()
                   ^^^^^^^^^^^^^^^^^^^^^^^^^^^^
  File "/home/airflow/.local/lib/python3.12/site-packages/airflow/models/dag.py", line 4081, in factory
    f(**f_kwargs)
  File "/opt/airflow/dags/DE_DP_dag.py", line 119, in my_text_classification_dag
    train_scoring = train_accuracy_scoring_task(df_trained)
                                                ^^^^^^^^^^
NameError: name 'df_trained' is not defined. Did you mean: 'ds_trained'?
[2024-05-18T17:57:09.145+0000] {processor.py:842} WARNING - No viable dags retrieved from /opt/airflow/dags/DE_DP_dag.py
[2024-05-18T17:57:09.172+0000] {processor.py:183} INFO - Processing /opt/airflow/dags/DE_DP_dag.py took 1.228 seconds
[2024-05-18T17:57:39.362+0000] {processor.py:161} INFO - Started process (PID=1812) to work on /opt/airflow/dags/DE_DP_dag.py
[2024-05-18T17:57:39.363+0000] {processor.py:830} INFO - Processing file /opt/airflow/dags/DE_DP_dag.py for tasks to queue
[2024-05-18T17:57:39.365+0000] {logging_mixin.py:188} INFO - [2024-05-18T17:57:39.365+0000] {dagbag.py:545} INFO - Filling up the DagBag from /opt/airflow/dags/DE_DP_dag.py
[2024-05-18T17:57:40.510+0000] {logging_mixin.py:188} INFO - [2024-05-18T17:57:40.504+0000] {dagbag.py:355} ERROR - Failed to import: /opt/airflow/dags/DE_DP_dag.py
Traceback (most recent call last):
  File "/home/airflow/.local/lib/python3.12/site-packages/airflow/models/dagbag.py", line 351, in parse
    loader.exec_module(new_module)
  File "<frozen importlib._bootstrap_external>", line 995, in exec_module
  File "<frozen importlib._bootstrap>", line 488, in _call_with_frames_removed
  File "/opt/airflow/dags/DE_DP_dag.py", line 130, in <module>
    dag_instance = my_text_classification_dag()
                   ^^^^^^^^^^^^^^^^^^^^^^^^^^^^
  File "/home/airflow/.local/lib/python3.12/site-packages/airflow/models/dag.py", line 4081, in factory
    f(**f_kwargs)
  File "/opt/airflow/dags/DE_DP_dag.py", line 119, in my_text_classification_dag
    train_scoring = train_accuracy_scoring_task(df_trained)
                                                ^^^^^^^^^^
NameError: name 'df_trained' is not defined. Did you mean: 'ds_trained'?
[2024-05-18T17:57:40.513+0000] {processor.py:842} WARNING - No viable dags retrieved from /opt/airflow/dags/DE_DP_dag.py
[2024-05-18T17:57:40.534+0000] {processor.py:183} INFO - Processing /opt/airflow/dags/DE_DP_dag.py took 1.181 seconds
[2024-05-18T17:58:10.722+0000] {processor.py:161} INFO - Started process (PID=1859) to work on /opt/airflow/dags/DE_DP_dag.py
[2024-05-18T17:58:10.723+0000] {processor.py:830} INFO - Processing file /opt/airflow/dags/DE_DP_dag.py for tasks to queue
[2024-05-18T17:58:10.725+0000] {logging_mixin.py:188} INFO - [2024-05-18T17:58:10.725+0000] {dagbag.py:545} INFO - Filling up the DagBag from /opt/airflow/dags/DE_DP_dag.py
[2024-05-18T17:58:11.908+0000] {logging_mixin.py:188} INFO - [2024-05-18T17:58:11.900+0000] {dagbag.py:355} ERROR - Failed to import: /opt/airflow/dags/DE_DP_dag.py
Traceback (most recent call last):
  File "/home/airflow/.local/lib/python3.12/site-packages/airflow/models/dagbag.py", line 351, in parse
    loader.exec_module(new_module)
  File "<frozen importlib._bootstrap_external>", line 995, in exec_module
  File "<frozen importlib._bootstrap>", line 488, in _call_with_frames_removed
  File "/opt/airflow/dags/DE_DP_dag.py", line 130, in <module>
    dag_instance = my_text_classification_dag()
                   ^^^^^^^^^^^^^^^^^^^^^^^^^^^^
  File "/home/airflow/.local/lib/python3.12/site-packages/airflow/models/dag.py", line 4081, in factory
    f(**f_kwargs)
  File "/opt/airflow/dags/DE_DP_dag.py", line 119, in my_text_classification_dag
    train_scoring = train_accuracy_scoring_task(df_trained)
                                                ^^^^^^^^^^
NameError: name 'df_trained' is not defined. Did you mean: 'ds_trained'?
[2024-05-18T17:58:11.911+0000] {processor.py:842} WARNING - No viable dags retrieved from /opt/airflow/dags/DE_DP_dag.py
[2024-05-18T17:58:11.936+0000] {processor.py:183} INFO - Processing /opt/airflow/dags/DE_DP_dag.py took 1.222 seconds
[2024-05-18T17:58:42.113+0000] {processor.py:161} INFO - Started process (PID=1906) to work on /opt/airflow/dags/DE_DP_dag.py
[2024-05-18T17:58:42.115+0000] {processor.py:830} INFO - Processing file /opt/airflow/dags/DE_DP_dag.py for tasks to queue
[2024-05-18T17:58:42.116+0000] {logging_mixin.py:188} INFO - [2024-05-18T17:58:42.116+0000] {dagbag.py:545} INFO - Filling up the DagBag from /opt/airflow/dags/DE_DP_dag.py
[2024-05-18T17:58:43.252+0000] {logging_mixin.py:188} INFO - [2024-05-18T17:58:43.245+0000] {dagbag.py:355} ERROR - Failed to import: /opt/airflow/dags/DE_DP_dag.py
Traceback (most recent call last):
  File "/home/airflow/.local/lib/python3.12/site-packages/airflow/models/dagbag.py", line 351, in parse
    loader.exec_module(new_module)
  File "<frozen importlib._bootstrap_external>", line 995, in exec_module
  File "<frozen importlib._bootstrap>", line 488, in _call_with_frames_removed
  File "/opt/airflow/dags/DE_DP_dag.py", line 130, in <module>
    dag_instance = my_text_classification_dag()
                   ^^^^^^^^^^^^^^^^^^^^^^^^^^^^
  File "/home/airflow/.local/lib/python3.12/site-packages/airflow/models/dag.py", line 4081, in factory
    f(**f_kwargs)
  File "/opt/airflow/dags/DE_DP_dag.py", line 119, in my_text_classification_dag
    train_scoring = train_accuracy_scoring_task(df_trained)
                                                ^^^^^^^^^^
NameError: name 'df_trained' is not defined. Did you mean: 'ds_trained'?
[2024-05-18T17:58:43.254+0000] {processor.py:842} WARNING - No viable dags retrieved from /opt/airflow/dags/DE_DP_dag.py
[2024-05-18T17:58:43.274+0000] {processor.py:183} INFO - Processing /opt/airflow/dags/DE_DP_dag.py took 1.167 seconds
[2024-05-18T17:59:13.462+0000] {processor.py:161} INFO - Started process (PID=1953) to work on /opt/airflow/dags/DE_DP_dag.py
[2024-05-18T17:59:13.464+0000] {processor.py:830} INFO - Processing file /opt/airflow/dags/DE_DP_dag.py for tasks to queue
[2024-05-18T17:59:13.466+0000] {logging_mixin.py:188} INFO - [2024-05-18T17:59:13.466+0000] {dagbag.py:545} INFO - Filling up the DagBag from /opt/airflow/dags/DE_DP_dag.py
[2024-05-18T17:59:14.702+0000] {logging_mixin.py:188} INFO - [2024-05-18T17:59:14.696+0000] {dagbag.py:355} ERROR - Failed to import: /opt/airflow/dags/DE_DP_dag.py
Traceback (most recent call last):
  File "/home/airflow/.local/lib/python3.12/site-packages/airflow/models/dagbag.py", line 351, in parse
    loader.exec_module(new_module)
  File "<frozen importlib._bootstrap_external>", line 995, in exec_module
  File "<frozen importlib._bootstrap>", line 488, in _call_with_frames_removed
  File "/opt/airflow/dags/DE_DP_dag.py", line 130, in <module>
    dag_instance = my_text_classification_dag()
                   ^^^^^^^^^^^^^^^^^^^^^^^^^^^^
  File "/home/airflow/.local/lib/python3.12/site-packages/airflow/models/dag.py", line 4081, in factory
    f(**f_kwargs)
  File "/opt/airflow/dags/DE_DP_dag.py", line 119, in my_text_classification_dag
    train_scoring = train_accuracy_scoring_task(df_trained)
                                                ^^^^^^^^^^
NameError: name 'df_trained' is not defined. Did you mean: 'ds_trained'?
[2024-05-18T17:59:14.705+0000] {processor.py:842} WARNING - No viable dags retrieved from /opt/airflow/dags/DE_DP_dag.py
[2024-05-18T17:59:14.731+0000] {processor.py:183} INFO - Processing /opt/airflow/dags/DE_DP_dag.py took 1.279 seconds
[2024-05-18T17:59:44.843+0000] {processor.py:161} INFO - Started process (PID=2000) to work on /opt/airflow/dags/DE_DP_dag.py
[2024-05-18T17:59:44.844+0000] {processor.py:830} INFO - Processing file /opt/airflow/dags/DE_DP_dag.py for tasks to queue
[2024-05-18T17:59:44.846+0000] {logging_mixin.py:188} INFO - [2024-05-18T17:59:44.846+0000] {dagbag.py:545} INFO - Filling up the DagBag from /opt/airflow/dags/DE_DP_dag.py
[2024-05-18T17:59:45.981+0000] {logging_mixin.py:188} INFO - [2024-05-18T17:59:45.974+0000] {dagbag.py:355} ERROR - Failed to import: /opt/airflow/dags/DE_DP_dag.py
Traceback (most recent call last):
  File "/home/airflow/.local/lib/python3.12/site-packages/airflow/models/dagbag.py", line 351, in parse
    loader.exec_module(new_module)
  File "<frozen importlib._bootstrap_external>", line 995, in exec_module
  File "<frozen importlib._bootstrap>", line 488, in _call_with_frames_removed
  File "/opt/airflow/dags/DE_DP_dag.py", line 130, in <module>
    dag_instance = my_text_classification_dag()
                   ^^^^^^^^^^^^^^^^^^^^^^^^^^^^
  File "/home/airflow/.local/lib/python3.12/site-packages/airflow/models/dag.py", line 4081, in factory
    f(**f_kwargs)
  File "/opt/airflow/dags/DE_DP_dag.py", line 119, in my_text_classification_dag
    train_scoring = train_accuracy_scoring_task(df_trained)
                                                ^^^^^^^^^^
NameError: name 'df_trained' is not defined. Did you mean: 'ds_trained'?
[2024-05-18T17:59:45.984+0000] {processor.py:842} WARNING - No viable dags retrieved from /opt/airflow/dags/DE_DP_dag.py
[2024-05-18T17:59:46.007+0000] {processor.py:183} INFO - Processing /opt/airflow/dags/DE_DP_dag.py took 1.170 seconds
[2024-05-18T18:00:16.068+0000] {processor.py:161} INFO - Started process (PID=2047) to work on /opt/airflow/dags/DE_DP_dag.py
[2024-05-18T18:00:16.070+0000] {processor.py:830} INFO - Processing file /opt/airflow/dags/DE_DP_dag.py for tasks to queue
[2024-05-18T18:00:16.072+0000] {logging_mixin.py:188} INFO - [2024-05-18T18:00:16.072+0000] {dagbag.py:545} INFO - Filling up the DagBag from /opt/airflow/dags/DE_DP_dag.py
[2024-05-18T18:00:17.215+0000] {logging_mixin.py:188} INFO - [2024-05-18T18:00:17.208+0000] {dagbag.py:355} ERROR - Failed to import: /opt/airflow/dags/DE_DP_dag.py
Traceback (most recent call last):
  File "/home/airflow/.local/lib/python3.12/site-packages/airflow/models/dagbag.py", line 351, in parse
    loader.exec_module(new_module)
  File "<frozen importlib._bootstrap_external>", line 995, in exec_module
  File "<frozen importlib._bootstrap>", line 488, in _call_with_frames_removed
  File "/opt/airflow/dags/DE_DP_dag.py", line 130, in <module>
    dag_instance = my_text_classification_dag()
                   ^^^^^^^^^^^^^^^^^^^^^^^^^^^^
  File "/home/airflow/.local/lib/python3.12/site-packages/airflow/models/dag.py", line 4081, in factory
    f(**f_kwargs)
  File "/opt/airflow/dags/DE_DP_dag.py", line 119, in my_text_classification_dag
    train_scoring = train_accuracy_scoring_task(df_trained)
                                                ^^^^^^^^^^
NameError: name 'df_trained' is not defined. Did you mean: 'ds_trained'?
[2024-05-18T18:00:17.218+0000] {processor.py:842} WARNING - No viable dags retrieved from /opt/airflow/dags/DE_DP_dag.py
[2024-05-18T18:00:17.245+0000] {processor.py:183} INFO - Processing /opt/airflow/dags/DE_DP_dag.py took 1.184 seconds
[2024-05-18T18:00:47.349+0000] {processor.py:161} INFO - Started process (PID=2094) to work on /opt/airflow/dags/DE_DP_dag.py
[2024-05-18T18:00:47.353+0000] {processor.py:830} INFO - Processing file /opt/airflow/dags/DE_DP_dag.py for tasks to queue
[2024-05-18T18:00:47.355+0000] {logging_mixin.py:188} INFO - [2024-05-18T18:00:47.354+0000] {dagbag.py:545} INFO - Filling up the DagBag from /opt/airflow/dags/DE_DP_dag.py
[2024-05-18T18:00:48.514+0000] {logging_mixin.py:188} INFO - [2024-05-18T18:00:48.506+0000] {dagbag.py:355} ERROR - Failed to import: /opt/airflow/dags/DE_DP_dag.py
Traceback (most recent call last):
  File "/home/airflow/.local/lib/python3.12/site-packages/airflow/models/dagbag.py", line 351, in parse
    loader.exec_module(new_module)
  File "<frozen importlib._bootstrap_external>", line 995, in exec_module
  File "<frozen importlib._bootstrap>", line 488, in _call_with_frames_removed
  File "/opt/airflow/dags/DE_DP_dag.py", line 130, in <module>
    dag_instance = my_text_classification_dag()
                   ^^^^^^^^^^^^^^^^^^^^^^^^^^^^
  File "/home/airflow/.local/lib/python3.12/site-packages/airflow/models/dag.py", line 4081, in factory
    f(**f_kwargs)
  File "/opt/airflow/dags/DE_DP_dag.py", line 119, in my_text_classification_dag
    train_scoring = train_accuracy_scoring_task(df_trained)
                                                ^^^^^^^^^^
NameError: name 'df_trained' is not defined. Did you mean: 'ds_trained'?
[2024-05-18T18:00:48.516+0000] {processor.py:842} WARNING - No viable dags retrieved from /opt/airflow/dags/DE_DP_dag.py
[2024-05-18T18:00:48.541+0000] {processor.py:183} INFO - Processing /opt/airflow/dags/DE_DP_dag.py took 1.200 seconds
[2024-05-18T18:01:18.718+0000] {processor.py:161} INFO - Started process (PID=2141) to work on /opt/airflow/dags/DE_DP_dag.py
[2024-05-18T18:01:18.719+0000] {processor.py:830} INFO - Processing file /opt/airflow/dags/DE_DP_dag.py for tasks to queue
[2024-05-18T18:01:18.721+0000] {logging_mixin.py:188} INFO - [2024-05-18T18:01:18.721+0000] {dagbag.py:545} INFO - Filling up the DagBag from /opt/airflow/dags/DE_DP_dag.py
[2024-05-18T18:01:19.873+0000] {logging_mixin.py:188} INFO - [2024-05-18T18:01:19.864+0000] {dagbag.py:355} ERROR - Failed to import: /opt/airflow/dags/DE_DP_dag.py
Traceback (most recent call last):
  File "/home/airflow/.local/lib/python3.12/site-packages/airflow/models/dagbag.py", line 351, in parse
    loader.exec_module(new_module)
  File "<frozen importlib._bootstrap_external>", line 995, in exec_module
  File "<frozen importlib._bootstrap>", line 488, in _call_with_frames_removed
  File "/opt/airflow/dags/DE_DP_dag.py", line 130, in <module>
    dag_instance = my_text_classification_dag()
                   ^^^^^^^^^^^^^^^^^^^^^^^^^^^^
  File "/home/airflow/.local/lib/python3.12/site-packages/airflow/models/dag.py", line 4081, in factory
    f(**f_kwargs)
  File "/opt/airflow/dags/DE_DP_dag.py", line 119, in my_text_classification_dag
    train_scoring = train_accuracy_scoring_task(df_trained)
                                                ^^^^^^^^^^
NameError: name 'df_trained' is not defined. Did you mean: 'ds_trained'?
[2024-05-18T18:01:19.876+0000] {processor.py:842} WARNING - No viable dags retrieved from /opt/airflow/dags/DE_DP_dag.py
[2024-05-18T18:01:19.901+0000] {processor.py:183} INFO - Processing /opt/airflow/dags/DE_DP_dag.py took 1.189 seconds
[2024-05-18T18:01:50.090+0000] {processor.py:161} INFO - Started process (PID=2188) to work on /opt/airflow/dags/DE_DP_dag.py
[2024-05-18T18:01:50.091+0000] {processor.py:830} INFO - Processing file /opt/airflow/dags/DE_DP_dag.py for tasks to queue
[2024-05-18T18:01:50.093+0000] {logging_mixin.py:188} INFO - [2024-05-18T18:01:50.093+0000] {dagbag.py:545} INFO - Filling up the DagBag from /opt/airflow/dags/DE_DP_dag.py
[2024-05-18T18:01:51.299+0000] {logging_mixin.py:188} INFO - [2024-05-18T18:01:51.292+0000] {dagbag.py:355} ERROR - Failed to import: /opt/airflow/dags/DE_DP_dag.py
Traceback (most recent call last):
  File "/home/airflow/.local/lib/python3.12/site-packages/airflow/models/dagbag.py", line 351, in parse
    loader.exec_module(new_module)
  File "<frozen importlib._bootstrap_external>", line 995, in exec_module
  File "<frozen importlib._bootstrap>", line 488, in _call_with_frames_removed
  File "/opt/airflow/dags/DE_DP_dag.py", line 130, in <module>
    dag_instance = my_text_classification_dag()
                   ^^^^^^^^^^^^^^^^^^^^^^^^^^^^
  File "/home/airflow/.local/lib/python3.12/site-packages/airflow/models/dag.py", line 4081, in factory
    f(**f_kwargs)
  File "/opt/airflow/dags/DE_DP_dag.py", line 119, in my_text_classification_dag
    train_scoring = train_accuracy_scoring_task(df_trained)
                                                ^^^^^^^^^^
NameError: name 'df_trained' is not defined. Did you mean: 'ds_trained'?
[2024-05-18T18:01:51.302+0000] {processor.py:842} WARNING - No viable dags retrieved from /opt/airflow/dags/DE_DP_dag.py
[2024-05-18T18:01:51.329+0000] {processor.py:183} INFO - Processing /opt/airflow/dags/DE_DP_dag.py took 1.245 seconds
[2024-05-18T18:02:21.510+0000] {processor.py:161} INFO - Started process (PID=2235) to work on /opt/airflow/dags/DE_DP_dag.py
[2024-05-18T18:02:21.511+0000] {processor.py:830} INFO - Processing file /opt/airflow/dags/DE_DP_dag.py for tasks to queue
[2024-05-18T18:02:21.514+0000] {logging_mixin.py:188} INFO - [2024-05-18T18:02:21.513+0000] {dagbag.py:545} INFO - Filling up the DagBag from /opt/airflow/dags/DE_DP_dag.py
[2024-05-18T18:02:22.632+0000] {logging_mixin.py:188} INFO - [2024-05-18T18:02:22.625+0000] {dagbag.py:355} ERROR - Failed to import: /opt/airflow/dags/DE_DP_dag.py
Traceback (most recent call last):
  File "/home/airflow/.local/lib/python3.12/site-packages/airflow/models/dagbag.py", line 351, in parse
    loader.exec_module(new_module)
  File "<frozen importlib._bootstrap_external>", line 995, in exec_module
  File "<frozen importlib._bootstrap>", line 488, in _call_with_frames_removed
  File "/opt/airflow/dags/DE_DP_dag.py", line 130, in <module>
    dag_instance = my_text_classification_dag()
                   ^^^^^^^^^^^^^^^^^^^^^^^^^^^^
  File "/home/airflow/.local/lib/python3.12/site-packages/airflow/models/dag.py", line 4081, in factory
    f(**f_kwargs)
  File "/opt/airflow/dags/DE_DP_dag.py", line 119, in my_text_classification_dag
    train_scoring = train_accuracy_scoring_task(df_trained)
                                                ^^^^^^^^^^
NameError: name 'df_trained' is not defined. Did you mean: 'ds_trained'?
[2024-05-18T18:02:22.635+0000] {processor.py:842} WARNING - No viable dags retrieved from /opt/airflow/dags/DE_DP_dag.py
[2024-05-18T18:02:22.661+0000] {processor.py:183} INFO - Processing /opt/airflow/dags/DE_DP_dag.py took 1.158 seconds
[2024-05-18T18:02:52.843+0000] {processor.py:161} INFO - Started process (PID=2282) to work on /opt/airflow/dags/DE_DP_dag.py
[2024-05-18T18:02:52.844+0000] {processor.py:830} INFO - Processing file /opt/airflow/dags/DE_DP_dag.py for tasks to queue
[2024-05-18T18:02:52.846+0000] {logging_mixin.py:188} INFO - [2024-05-18T18:02:52.846+0000] {dagbag.py:545} INFO - Filling up the DagBag from /opt/airflow/dags/DE_DP_dag.py
[2024-05-18T18:02:54.002+0000] {logging_mixin.py:188} INFO - [2024-05-18T18:02:53.994+0000] {dagbag.py:355} ERROR - Failed to import: /opt/airflow/dags/DE_DP_dag.py
Traceback (most recent call last):
  File "/home/airflow/.local/lib/python3.12/site-packages/airflow/models/dagbag.py", line 351, in parse
    loader.exec_module(new_module)
  File "<frozen importlib._bootstrap_external>", line 995, in exec_module
  File "<frozen importlib._bootstrap>", line 488, in _call_with_frames_removed
  File "/opt/airflow/dags/DE_DP_dag.py", line 130, in <module>
    dag_instance = my_text_classification_dag()
                   ^^^^^^^^^^^^^^^^^^^^^^^^^^^^
  File "/home/airflow/.local/lib/python3.12/site-packages/airflow/models/dag.py", line 4081, in factory
    f(**f_kwargs)
  File "/opt/airflow/dags/DE_DP_dag.py", line 119, in my_text_classification_dag
    train_scoring = train_accuracy_scoring_task(df_trained)
                                                ^^^^^^^^^^
NameError: name 'df_trained' is not defined. Did you mean: 'ds_trained'?
[2024-05-18T18:02:54.005+0000] {processor.py:842} WARNING - No viable dags retrieved from /opt/airflow/dags/DE_DP_dag.py
[2024-05-18T18:02:54.031+0000] {processor.py:183} INFO - Processing /opt/airflow/dags/DE_DP_dag.py took 1.196 seconds
[2024-05-18T18:03:24.215+0000] {processor.py:161} INFO - Started process (PID=2329) to work on /opt/airflow/dags/DE_DP_dag.py
[2024-05-18T18:03:24.216+0000] {processor.py:830} INFO - Processing file /opt/airflow/dags/DE_DP_dag.py for tasks to queue
[2024-05-18T18:03:24.218+0000] {logging_mixin.py:188} INFO - [2024-05-18T18:03:24.218+0000] {dagbag.py:545} INFO - Filling up the DagBag from /opt/airflow/dags/DE_DP_dag.py
[2024-05-18T18:03:25.413+0000] {logging_mixin.py:188} INFO - [2024-05-18T18:03:25.405+0000] {dagbag.py:355} ERROR - Failed to import: /opt/airflow/dags/DE_DP_dag.py
Traceback (most recent call last):
  File "/home/airflow/.local/lib/python3.12/site-packages/airflow/models/dagbag.py", line 351, in parse
    loader.exec_module(new_module)
  File "<frozen importlib._bootstrap_external>", line 995, in exec_module
  File "<frozen importlib._bootstrap>", line 488, in _call_with_frames_removed
  File "/opt/airflow/dags/DE_DP_dag.py", line 130, in <module>
    dag_instance = my_text_classification_dag()
                   ^^^^^^^^^^^^^^^^^^^^^^^^^^^^
  File "/home/airflow/.local/lib/python3.12/site-packages/airflow/models/dag.py", line 4081, in factory
    f(**f_kwargs)
  File "/opt/airflow/dags/DE_DP_dag.py", line 119, in my_text_classification_dag
    train_scoring = train_accuracy_scoring_task(df_trained)
                                                ^^^^^^^^^^
NameError: name 'df_trained' is not defined. Did you mean: 'ds_trained'?
[2024-05-18T18:03:25.415+0000] {processor.py:842} WARNING - No viable dags retrieved from /opt/airflow/dags/DE_DP_dag.py
[2024-05-18T18:03:25.439+0000] {processor.py:183} INFO - Processing /opt/airflow/dags/DE_DP_dag.py took 1.230 seconds
[2024-05-18T18:03:55.618+0000] {processor.py:161} INFO - Started process (PID=2376) to work on /opt/airflow/dags/DE_DP_dag.py
[2024-05-18T18:03:55.619+0000] {processor.py:830} INFO - Processing file /opt/airflow/dags/DE_DP_dag.py for tasks to queue
[2024-05-18T18:03:55.621+0000] {logging_mixin.py:188} INFO - [2024-05-18T18:03:55.621+0000] {dagbag.py:545} INFO - Filling up the DagBag from /opt/airflow/dags/DE_DP_dag.py
[2024-05-18T18:03:56.801+0000] {logging_mixin.py:188} INFO - [2024-05-18T18:03:56.795+0000] {dagbag.py:355} ERROR - Failed to import: /opt/airflow/dags/DE_DP_dag.py
Traceback (most recent call last):
  File "/home/airflow/.local/lib/python3.12/site-packages/airflow/models/dagbag.py", line 351, in parse
    loader.exec_module(new_module)
  File "<frozen importlib._bootstrap_external>", line 995, in exec_module
  File "<frozen importlib._bootstrap>", line 488, in _call_with_frames_removed
  File "/opt/airflow/dags/DE_DP_dag.py", line 130, in <module>
    dag_instance = my_text_classification_dag()
                   ^^^^^^^^^^^^^^^^^^^^^^^^^^^^
  File "/home/airflow/.local/lib/python3.12/site-packages/airflow/models/dag.py", line 4081, in factory
    f(**f_kwargs)
  File "/opt/airflow/dags/DE_DP_dag.py", line 119, in my_text_classification_dag
    train_scoring = train_accuracy_scoring_task(df_trained)
                                                ^^^^^^^^^^
NameError: name 'df_trained' is not defined. Did you mean: 'ds_trained'?
[2024-05-18T18:03:56.804+0000] {processor.py:842} WARNING - No viable dags retrieved from /opt/airflow/dags/DE_DP_dag.py
[2024-05-18T18:03:56.829+0000] {processor.py:183} INFO - Processing /opt/airflow/dags/DE_DP_dag.py took 1.216 seconds
[2024-05-18T18:04:27.050+0000] {processor.py:161} INFO - Started process (PID=2423) to work on /opt/airflow/dags/DE_DP_dag.py
[2024-05-18T18:04:27.051+0000] {processor.py:830} INFO - Processing file /opt/airflow/dags/DE_DP_dag.py for tasks to queue
[2024-05-18T18:04:27.053+0000] {logging_mixin.py:188} INFO - [2024-05-18T18:04:27.053+0000] {dagbag.py:545} INFO - Filling up the DagBag from /opt/airflow/dags/DE_DP_dag.py
[2024-05-18T18:04:28.197+0000] {logging_mixin.py:188} INFO - [2024-05-18T18:04:28.187+0000] {dagbag.py:355} ERROR - Failed to import: /opt/airflow/dags/DE_DP_dag.py
Traceback (most recent call last):
  File "/home/airflow/.local/lib/python3.12/site-packages/airflow/models/dagbag.py", line 351, in parse
    loader.exec_module(new_module)
  File "<frozen importlib._bootstrap_external>", line 995, in exec_module
  File "<frozen importlib._bootstrap>", line 488, in _call_with_frames_removed
  File "/opt/airflow/dags/DE_DP_dag.py", line 130, in <module>
    dag_instance = my_text_classification_dag()
                   ^^^^^^^^^^^^^^^^^^^^^^^^^^^^
  File "/home/airflow/.local/lib/python3.12/site-packages/airflow/models/dag.py", line 4081, in factory
    f(**f_kwargs)
  File "/opt/airflow/dags/DE_DP_dag.py", line 119, in my_text_classification_dag
    train_scoring = train_accuracy_scoring_task(df_trained)
                                                ^^^^^^^^^^
NameError: name 'df_trained' is not defined. Did you mean: 'ds_trained'?
[2024-05-18T18:04:28.200+0000] {processor.py:842} WARNING - No viable dags retrieved from /opt/airflow/dags/DE_DP_dag.py
[2024-05-18T18:04:28.226+0000] {processor.py:183} INFO - Processing /opt/airflow/dags/DE_DP_dag.py took 1.182 seconds
[2024-05-18T18:04:58.414+0000] {processor.py:161} INFO - Started process (PID=2470) to work on /opt/airflow/dags/DE_DP_dag.py
[2024-05-18T18:04:58.415+0000] {processor.py:830} INFO - Processing file /opt/airflow/dags/DE_DP_dag.py for tasks to queue
[2024-05-18T18:04:58.417+0000] {logging_mixin.py:188} INFO - [2024-05-18T18:04:58.417+0000] {dagbag.py:545} INFO - Filling up the DagBag from /opt/airflow/dags/DE_DP_dag.py
[2024-05-18T18:04:59.683+0000] {logging_mixin.py:188} INFO - [2024-05-18T18:04:59.676+0000] {dagbag.py:355} ERROR - Failed to import: /opt/airflow/dags/DE_DP_dag.py
Traceback (most recent call last):
  File "/home/airflow/.local/lib/python3.12/site-packages/airflow/models/dagbag.py", line 351, in parse
    loader.exec_module(new_module)
  File "<frozen importlib._bootstrap_external>", line 995, in exec_module
  File "<frozen importlib._bootstrap>", line 488, in _call_with_frames_removed
  File "/opt/airflow/dags/DE_DP_dag.py", line 130, in <module>
    dag_instance = my_text_classification_dag()
                   ^^^^^^^^^^^^^^^^^^^^^^^^^^^^
  File "/home/airflow/.local/lib/python3.12/site-packages/airflow/models/dag.py", line 4081, in factory
    f(**f_kwargs)
  File "/opt/airflow/dags/DE_DP_dag.py", line 119, in my_text_classification_dag
    train_scoring = train_accuracy_scoring_task(df_trained)
                                                ^^^^^^^^^^
NameError: name 'df_trained' is not defined. Did you mean: 'ds_trained'?
[2024-05-18T18:04:59.686+0000] {processor.py:842} WARNING - No viable dags retrieved from /opt/airflow/dags/DE_DP_dag.py
[2024-05-18T18:04:59.714+0000] {processor.py:183} INFO - Processing /opt/airflow/dags/DE_DP_dag.py took 1.305 seconds
[2024-05-18T18:05:29.907+0000] {processor.py:161} INFO - Started process (PID=2517) to work on /opt/airflow/dags/DE_DP_dag.py
[2024-05-18T18:05:29.908+0000] {processor.py:830} INFO - Processing file /opt/airflow/dags/DE_DP_dag.py for tasks to queue
[2024-05-18T18:05:29.911+0000] {logging_mixin.py:188} INFO - [2024-05-18T18:05:29.910+0000] {dagbag.py:545} INFO - Filling up the DagBag from /opt/airflow/dags/DE_DP_dag.py
[2024-05-18T18:05:31.093+0000] {logging_mixin.py:188} INFO - [2024-05-18T18:05:31.085+0000] {dagbag.py:355} ERROR - Failed to import: /opt/airflow/dags/DE_DP_dag.py
Traceback (most recent call last):
  File "/home/airflow/.local/lib/python3.12/site-packages/airflow/models/dagbag.py", line 351, in parse
    loader.exec_module(new_module)
  File "<frozen importlib._bootstrap_external>", line 995, in exec_module
  File "<frozen importlib._bootstrap>", line 488, in _call_with_frames_removed
  File "/opt/airflow/dags/DE_DP_dag.py", line 130, in <module>
    dag_instance = my_text_classification_dag()
                   ^^^^^^^^^^^^^^^^^^^^^^^^^^^^
  File "/home/airflow/.local/lib/python3.12/site-packages/airflow/models/dag.py", line 4081, in factory
    f(**f_kwargs)
  File "/opt/airflow/dags/DE_DP_dag.py", line 119, in my_text_classification_dag
    train_scoring = train_accuracy_scoring_task(df_trained)
                                                ^^^^^^^^^^
NameError: name 'df_trained' is not defined. Did you mean: 'ds_trained'?
[2024-05-18T18:05:31.095+0000] {processor.py:842} WARNING - No viable dags retrieved from /opt/airflow/dags/DE_DP_dag.py
[2024-05-18T18:05:31.121+0000] {processor.py:183} INFO - Processing /opt/airflow/dags/DE_DP_dag.py took 1.222 seconds
[2024-05-18T18:06:01.317+0000] {processor.py:161} INFO - Started process (PID=2564) to work on /opt/airflow/dags/DE_DP_dag.py
[2024-05-18T18:06:01.319+0000] {processor.py:830} INFO - Processing file /opt/airflow/dags/DE_DP_dag.py for tasks to queue
[2024-05-18T18:06:01.321+0000] {logging_mixin.py:188} INFO - [2024-05-18T18:06:01.321+0000] {dagbag.py:545} INFO - Filling up the DagBag from /opt/airflow/dags/DE_DP_dag.py
[2024-05-18T18:06:02.598+0000] {logging_mixin.py:188} INFO - [2024-05-18T18:06:02.591+0000] {dagbag.py:355} ERROR - Failed to import: /opt/airflow/dags/DE_DP_dag.py
Traceback (most recent call last):
  File "/home/airflow/.local/lib/python3.12/site-packages/airflow/models/dagbag.py", line 351, in parse
    loader.exec_module(new_module)
  File "<frozen importlib._bootstrap_external>", line 995, in exec_module
  File "<frozen importlib._bootstrap>", line 488, in _call_with_frames_removed
  File "/opt/airflow/dags/DE_DP_dag.py", line 130, in <module>
    dag_instance = my_text_classification_dag()
                   ^^^^^^^^^^^^^^^^^^^^^^^^^^^^
  File "/home/airflow/.local/lib/python3.12/site-packages/airflow/models/dag.py", line 4081, in factory
    f(**f_kwargs)
  File "/opt/airflow/dags/DE_DP_dag.py", line 119, in my_text_classification_dag
    train_scoring = train_accuracy_scoring_task(df_trained)
                                                ^^^^^^^^^^
NameError: name 'df_trained' is not defined. Did you mean: 'ds_trained'?
[2024-05-18T18:06:02.601+0000] {processor.py:842} WARNING - No viable dags retrieved from /opt/airflow/dags/DE_DP_dag.py
[2024-05-18T18:06:02.630+0000] {processor.py:183} INFO - Processing /opt/airflow/dags/DE_DP_dag.py took 1.323 seconds
[2024-05-18T18:06:32.824+0000] {processor.py:161} INFO - Started process (PID=2611) to work on /opt/airflow/dags/DE_DP_dag.py
[2024-05-18T18:06:32.826+0000] {processor.py:830} INFO - Processing file /opt/airflow/dags/DE_DP_dag.py for tasks to queue
[2024-05-18T18:06:32.829+0000] {logging_mixin.py:188} INFO - [2024-05-18T18:06:32.828+0000] {dagbag.py:545} INFO - Filling up the DagBag from /opt/airflow/dags/DE_DP_dag.py
[2024-05-18T18:06:33.983+0000] {logging_mixin.py:188} INFO - [2024-05-18T18:06:33.976+0000] {dagbag.py:355} ERROR - Failed to import: /opt/airflow/dags/DE_DP_dag.py
Traceback (most recent call last):
  File "/home/airflow/.local/lib/python3.12/site-packages/airflow/models/dagbag.py", line 351, in parse
    loader.exec_module(new_module)
  File "<frozen importlib._bootstrap_external>", line 995, in exec_module
  File "<frozen importlib._bootstrap>", line 488, in _call_with_frames_removed
  File "/opt/airflow/dags/DE_DP_dag.py", line 130, in <module>
    dag_instance = my_text_classification_dag()
                   ^^^^^^^^^^^^^^^^^^^^^^^^^^^^
  File "/home/airflow/.local/lib/python3.12/site-packages/airflow/models/dag.py", line 4081, in factory
    f(**f_kwargs)
  File "/opt/airflow/dags/DE_DP_dag.py", line 119, in my_text_classification_dag
    train_scoring = train_accuracy_scoring_task(df_trained)
                                                ^^^^^^^^^^
NameError: name 'df_trained' is not defined. Did you mean: 'ds_trained'?
[2024-05-18T18:06:33.985+0000] {processor.py:842} WARNING - No viable dags retrieved from /opt/airflow/dags/DE_DP_dag.py
[2024-05-18T18:06:34.014+0000] {processor.py:183} INFO - Processing /opt/airflow/dags/DE_DP_dag.py took 1.197 seconds
[2024-05-18T18:07:04.223+0000] {processor.py:161} INFO - Started process (PID=2658) to work on /opt/airflow/dags/DE_DP_dag.py
[2024-05-18T18:07:04.224+0000] {processor.py:830} INFO - Processing file /opt/airflow/dags/DE_DP_dag.py for tasks to queue
[2024-05-18T18:07:04.226+0000] {logging_mixin.py:188} INFO - [2024-05-18T18:07:04.226+0000] {dagbag.py:545} INFO - Filling up the DagBag from /opt/airflow/dags/DE_DP_dag.py
[2024-05-18T18:07:05.360+0000] {logging_mixin.py:188} INFO - [2024-05-18T18:07:05.352+0000] {dagbag.py:355} ERROR - Failed to import: /opt/airflow/dags/DE_DP_dag.py
Traceback (most recent call last):
  File "/home/airflow/.local/lib/python3.12/site-packages/airflow/models/dagbag.py", line 351, in parse
    loader.exec_module(new_module)
  File "<frozen importlib._bootstrap_external>", line 995, in exec_module
  File "<frozen importlib._bootstrap>", line 488, in _call_with_frames_removed
  File "/opt/airflow/dags/DE_DP_dag.py", line 130, in <module>
    dag_instance = my_text_classification_dag()
                   ^^^^^^^^^^^^^^^^^^^^^^^^^^^^
  File "/home/airflow/.local/lib/python3.12/site-packages/airflow/models/dag.py", line 4081, in factory
    f(**f_kwargs)
  File "/opt/airflow/dags/DE_DP_dag.py", line 119, in my_text_classification_dag
    train_scoring = train_accuracy_scoring_task(df_trained)
                                                ^^^^^^^^^^
NameError: name 'df_trained' is not defined. Did you mean: 'ds_trained'?
[2024-05-18T18:07:05.362+0000] {processor.py:842} WARNING - No viable dags retrieved from /opt/airflow/dags/DE_DP_dag.py
[2024-05-18T18:07:05.387+0000] {processor.py:183} INFO - Processing /opt/airflow/dags/DE_DP_dag.py took 1.173 seconds
[2024-05-18T18:07:35.568+0000] {processor.py:161} INFO - Started process (PID=2705) to work on /opt/airflow/dags/DE_DP_dag.py
[2024-05-18T18:07:35.569+0000] {processor.py:830} INFO - Processing file /opt/airflow/dags/DE_DP_dag.py for tasks to queue
[2024-05-18T18:07:35.572+0000] {logging_mixin.py:188} INFO - [2024-05-18T18:07:35.571+0000] {dagbag.py:545} INFO - Filling up the DagBag from /opt/airflow/dags/DE_DP_dag.py
[2024-05-18T18:07:36.667+0000] {logging_mixin.py:188} INFO - [2024-05-18T18:07:36.659+0000] {dagbag.py:355} ERROR - Failed to import: /opt/airflow/dags/DE_DP_dag.py
Traceback (most recent call last):
  File "/home/airflow/.local/lib/python3.12/site-packages/airflow/models/dagbag.py", line 351, in parse
    loader.exec_module(new_module)
  File "<frozen importlib._bootstrap_external>", line 995, in exec_module
  File "<frozen importlib._bootstrap>", line 488, in _call_with_frames_removed
  File "/opt/airflow/dags/DE_DP_dag.py", line 130, in <module>
    dag_instance = my_text_classification_dag()
                   ^^^^^^^^^^^^^^^^^^^^^^^^^^^^
  File "/home/airflow/.local/lib/python3.12/site-packages/airflow/models/dag.py", line 4081, in factory
    f(**f_kwargs)
  File "/opt/airflow/dags/DE_DP_dag.py", line 119, in my_text_classification_dag
    train_scoring = train_accuracy_scoring_task(df_trained)
                                                ^^^^^^^^^^
NameError: name 'df_trained' is not defined. Did you mean: 'ds_trained'?
[2024-05-18T18:07:36.670+0000] {processor.py:842} WARNING - No viable dags retrieved from /opt/airflow/dags/DE_DP_dag.py
[2024-05-18T18:07:36.693+0000] {processor.py:183} INFO - Processing /opt/airflow/dags/DE_DP_dag.py took 1.131 seconds
[2024-05-18T18:08:06.872+0000] {processor.py:161} INFO - Started process (PID=2752) to work on /opt/airflow/dags/DE_DP_dag.py
[2024-05-18T18:08:06.873+0000] {processor.py:830} INFO - Processing file /opt/airflow/dags/DE_DP_dag.py for tasks to queue
[2024-05-18T18:08:06.875+0000] {logging_mixin.py:188} INFO - [2024-05-18T18:08:06.875+0000] {dagbag.py:545} INFO - Filling up the DagBag from /opt/airflow/dags/DE_DP_dag.py
[2024-05-18T18:08:07.925+0000] {logging_mixin.py:188} INFO - [2024-05-18T18:08:07.918+0000] {dagbag.py:355} ERROR - Failed to import: /opt/airflow/dags/DE_DP_dag.py
Traceback (most recent call last):
  File "/home/airflow/.local/lib/python3.12/site-packages/airflow/models/dagbag.py", line 351, in parse
    loader.exec_module(new_module)
  File "<frozen importlib._bootstrap_external>", line 995, in exec_module
  File "<frozen importlib._bootstrap>", line 488, in _call_with_frames_removed
  File "/opt/airflow/dags/DE_DP_dag.py", line 130, in <module>
    dag_instance = my_text_classification_dag()
                   ^^^^^^^^^^^^^^^^^^^^^^^^^^^^
  File "/home/airflow/.local/lib/python3.12/site-packages/airflow/models/dag.py", line 4081, in factory
    f(**f_kwargs)
  File "/opt/airflow/dags/DE_DP_dag.py", line 119, in my_text_classification_dag
    train_scoring = train_accuracy_scoring_task(df_trained)
                                                ^^^^^^^^^^
NameError: name 'df_trained' is not defined. Did you mean: 'ds_trained'?
[2024-05-18T18:08:07.927+0000] {processor.py:842} WARNING - No viable dags retrieved from /opt/airflow/dags/DE_DP_dag.py
[2024-05-18T18:08:07.950+0000] {processor.py:183} INFO - Processing /opt/airflow/dags/DE_DP_dag.py took 1.084 seconds
[2024-05-18T18:08:38.044+0000] {processor.py:161} INFO - Started process (PID=2799) to work on /opt/airflow/dags/DE_DP_dag.py
[2024-05-18T18:08:38.045+0000] {processor.py:830} INFO - Processing file /opt/airflow/dags/DE_DP_dag.py for tasks to queue
[2024-05-18T18:08:38.047+0000] {logging_mixin.py:188} INFO - [2024-05-18T18:08:38.047+0000] {dagbag.py:545} INFO - Filling up the DagBag from /opt/airflow/dags/DE_DP_dag.py
[2024-05-18T18:08:39.119+0000] {logging_mixin.py:188} INFO - [2024-05-18T18:08:39.114+0000] {dagbag.py:355} ERROR - Failed to import: /opt/airflow/dags/DE_DP_dag.py
Traceback (most recent call last):
  File "/home/airflow/.local/lib/python3.12/site-packages/airflow/models/dagbag.py", line 351, in parse
    loader.exec_module(new_module)
  File "<frozen importlib._bootstrap_external>", line 995, in exec_module
  File "<frozen importlib._bootstrap>", line 488, in _call_with_frames_removed
  File "/opt/airflow/dags/DE_DP_dag.py", line 130, in <module>
    dag_instance = my_text_classification_dag()
                   ^^^^^^^^^^^^^^^^^^^^^^^^^^^^
  File "/home/airflow/.local/lib/python3.12/site-packages/airflow/models/dag.py", line 4081, in factory
    f(**f_kwargs)
  File "/opt/airflow/dags/DE_DP_dag.py", line 119, in my_text_classification_dag
    train_scoring = train_accuracy_scoring_task(df_trained)
                                                ^^^^^^^^^^
NameError: name 'df_trained' is not defined. Did you mean: 'ds_trained'?
[2024-05-18T18:08:39.122+0000] {processor.py:842} WARNING - No viable dags retrieved from /opt/airflow/dags/DE_DP_dag.py
[2024-05-18T18:08:39.148+0000] {processor.py:183} INFO - Processing /opt/airflow/dags/DE_DP_dag.py took 1.110 seconds
[2024-05-18T18:09:09.285+0000] {processor.py:161} INFO - Started process (PID=2846) to work on /opt/airflow/dags/DE_DP_dag.py
[2024-05-18T18:09:09.287+0000] {processor.py:830} INFO - Processing file /opt/airflow/dags/DE_DP_dag.py for tasks to queue
[2024-05-18T18:09:09.289+0000] {logging_mixin.py:188} INFO - [2024-05-18T18:09:09.289+0000] {dagbag.py:545} INFO - Filling up the DagBag from /opt/airflow/dags/DE_DP_dag.py
[2024-05-18T18:09:10.445+0000] {logging_mixin.py:188} INFO - [2024-05-18T18:09:10.438+0000] {dagbag.py:355} ERROR - Failed to import: /opt/airflow/dags/DE_DP_dag.py
Traceback (most recent call last):
  File "/home/airflow/.local/lib/python3.12/site-packages/airflow/models/dagbag.py", line 351, in parse
    loader.exec_module(new_module)
  File "<frozen importlib._bootstrap_external>", line 995, in exec_module
  File "<frozen importlib._bootstrap>", line 488, in _call_with_frames_removed
  File "/opt/airflow/dags/DE_DP_dag.py", line 130, in <module>
    dag_instance = my_text_classification_dag()
                   ^^^^^^^^^^^^^^^^^^^^^^^^^^^^
  File "/home/airflow/.local/lib/python3.12/site-packages/airflow/models/dag.py", line 4081, in factory
    f(**f_kwargs)
  File "/opt/airflow/dags/DE_DP_dag.py", line 119, in my_text_classification_dag
    train_scoring = train_accuracy_scoring_task(df_trained)
                                                ^^^^^^^^^^
NameError: name 'df_trained' is not defined. Did you mean: 'ds_trained'?
[2024-05-18T18:09:10.447+0000] {processor.py:842} WARNING - No viable dags retrieved from /opt/airflow/dags/DE_DP_dag.py
[2024-05-18T18:09:10.470+0000] {processor.py:183} INFO - Processing /opt/airflow/dags/DE_DP_dag.py took 1.191 seconds
[2024-05-18T18:09:40.664+0000] {processor.py:161} INFO - Started process (PID=2893) to work on /opt/airflow/dags/DE_DP_dag.py
[2024-05-18T18:09:40.665+0000] {processor.py:830} INFO - Processing file /opt/airflow/dags/DE_DP_dag.py for tasks to queue
[2024-05-18T18:09:40.667+0000] {logging_mixin.py:188} INFO - [2024-05-18T18:09:40.666+0000] {dagbag.py:545} INFO - Filling up the DagBag from /opt/airflow/dags/DE_DP_dag.py
[2024-05-18T18:09:41.747+0000] {logging_mixin.py:188} INFO - [2024-05-18T18:09:41.740+0000] {dagbag.py:355} ERROR - Failed to import: /opt/airflow/dags/DE_DP_dag.py
Traceback (most recent call last):
  File "/home/airflow/.local/lib/python3.12/site-packages/airflow/models/dagbag.py", line 351, in parse
    loader.exec_module(new_module)
  File "<frozen importlib._bootstrap_external>", line 995, in exec_module
  File "<frozen importlib._bootstrap>", line 488, in _call_with_frames_removed
  File "/opt/airflow/dags/DE_DP_dag.py", line 130, in <module>
    dag_instance = my_text_classification_dag()
                   ^^^^^^^^^^^^^^^^^^^^^^^^^^^^
  File "/home/airflow/.local/lib/python3.12/site-packages/airflow/models/dag.py", line 4081, in factory
    f(**f_kwargs)
  File "/opt/airflow/dags/DE_DP_dag.py", line 119, in my_text_classification_dag
    train_scoring = train_accuracy_scoring_task(df_trained)
                                                ^^^^^^^^^^
NameError: name 'df_trained' is not defined. Did you mean: 'ds_trained'?
[2024-05-18T18:09:41.750+0000] {processor.py:842} WARNING - No viable dags retrieved from /opt/airflow/dags/DE_DP_dag.py
[2024-05-18T18:09:41.770+0000] {processor.py:183} INFO - Processing /opt/airflow/dags/DE_DP_dag.py took 1.112 seconds
[2024-05-18T18:10:11.834+0000] {processor.py:161} INFO - Started process (PID=2940) to work on /opt/airflow/dags/DE_DP_dag.py
[2024-05-18T18:10:11.835+0000] {processor.py:830} INFO - Processing file /opt/airflow/dags/DE_DP_dag.py for tasks to queue
[2024-05-18T18:10:11.837+0000] {logging_mixin.py:188} INFO - [2024-05-18T18:10:11.836+0000] {dagbag.py:545} INFO - Filling up the DagBag from /opt/airflow/dags/DE_DP_dag.py
[2024-05-18T18:10:12.867+0000] {logging_mixin.py:188} INFO - [2024-05-18T18:10:12.860+0000] {dagbag.py:355} ERROR - Failed to import: /opt/airflow/dags/DE_DP_dag.py
Traceback (most recent call last):
  File "/home/airflow/.local/lib/python3.12/site-packages/airflow/models/dagbag.py", line 351, in parse
    loader.exec_module(new_module)
  File "<frozen importlib._bootstrap_external>", line 995, in exec_module
  File "<frozen importlib._bootstrap>", line 488, in _call_with_frames_removed
  File "/opt/airflow/dags/DE_DP_dag.py", line 130, in <module>
    dag_instance = my_text_classification_dag()
                   ^^^^^^^^^^^^^^^^^^^^^^^^^^^^
  File "/home/airflow/.local/lib/python3.12/site-packages/airflow/models/dag.py", line 4081, in factory
    f(**f_kwargs)
  File "/opt/airflow/dags/DE_DP_dag.py", line 119, in my_text_classification_dag
    train_scoring = train_accuracy_scoring_task(df_trained)
                                                ^^^^^^^^^^
NameError: name 'df_trained' is not defined. Did you mean: 'ds_trained'?
[2024-05-18T18:10:12.869+0000] {processor.py:842} WARNING - No viable dags retrieved from /opt/airflow/dags/DE_DP_dag.py
[2024-05-18T18:10:12.892+0000] {processor.py:183} INFO - Processing /opt/airflow/dags/DE_DP_dag.py took 1.065 seconds
[2024-05-18T18:10:42.998+0000] {processor.py:161} INFO - Started process (PID=2987) to work on /opt/airflow/dags/DE_DP_dag.py
[2024-05-18T18:10:42.998+0000] {processor.py:830} INFO - Processing file /opt/airflow/dags/DE_DP_dag.py for tasks to queue
[2024-05-18T18:10:43.001+0000] {logging_mixin.py:188} INFO - [2024-05-18T18:10:43.000+0000] {dagbag.py:545} INFO - Filling up the DagBag from /opt/airflow/dags/DE_DP_dag.py
[2024-05-18T18:10:44.102+0000] {logging_mixin.py:188} INFO - [2024-05-18T18:10:44.094+0000] {dagbag.py:355} ERROR - Failed to import: /opt/airflow/dags/DE_DP_dag.py
Traceback (most recent call last):
  File "/home/airflow/.local/lib/python3.12/site-packages/airflow/models/dagbag.py", line 351, in parse
    loader.exec_module(new_module)
  File "<frozen importlib._bootstrap_external>", line 995, in exec_module
  File "<frozen importlib._bootstrap>", line 488, in _call_with_frames_removed
  File "/opt/airflow/dags/DE_DP_dag.py", line 130, in <module>
    dag_instance = my_text_classification_dag()
                   ^^^^^^^^^^^^^^^^^^^^^^^^^^^^
  File "/home/airflow/.local/lib/python3.12/site-packages/airflow/models/dag.py", line 4081, in factory
    f(**f_kwargs)
  File "/opt/airflow/dags/DE_DP_dag.py", line 119, in my_text_classification_dag
    train_scoring = train_accuracy_scoring_task(df_trained)
                                                ^^^^^^^^^^
NameError: name 'df_trained' is not defined. Did you mean: 'ds_trained'?
[2024-05-18T18:10:44.104+0000] {processor.py:842} WARNING - No viable dags retrieved from /opt/airflow/dags/DE_DP_dag.py
[2024-05-18T18:10:44.129+0000] {processor.py:183} INFO - Processing /opt/airflow/dags/DE_DP_dag.py took 1.139 seconds
[2024-05-18T18:11:14.198+0000] {processor.py:161} INFO - Started process (PID=3034) to work on /opt/airflow/dags/DE_DP_dag.py
[2024-05-18T18:11:14.199+0000] {processor.py:830} INFO - Processing file /opt/airflow/dags/DE_DP_dag.py for tasks to queue
[2024-05-18T18:11:14.201+0000] {logging_mixin.py:188} INFO - [2024-05-18T18:11:14.201+0000] {dagbag.py:545} INFO - Filling up the DagBag from /opt/airflow/dags/DE_DP_dag.py
[2024-05-18T18:11:15.255+0000] {logging_mixin.py:188} INFO - [2024-05-18T18:11:15.248+0000] {dagbag.py:355} ERROR - Failed to import: /opt/airflow/dags/DE_DP_dag.py
Traceback (most recent call last):
  File "/home/airflow/.local/lib/python3.12/site-packages/airflow/models/dagbag.py", line 351, in parse
    loader.exec_module(new_module)
  File "<frozen importlib._bootstrap_external>", line 995, in exec_module
  File "<frozen importlib._bootstrap>", line 488, in _call_with_frames_removed
  File "/opt/airflow/dags/DE_DP_dag.py", line 130, in <module>
    dag_instance = my_text_classification_dag()
                   ^^^^^^^^^^^^^^^^^^^^^^^^^^^^
  File "/home/airflow/.local/lib/python3.12/site-packages/airflow/models/dag.py", line 4081, in factory
    f(**f_kwargs)
  File "/opt/airflow/dags/DE_DP_dag.py", line 119, in my_text_classification_dag
    train_scoring = train_accuracy_scoring_task(df_trained)
                                                ^^^^^^^^^^
NameError: name 'df_trained' is not defined. Did you mean: 'ds_trained'?
[2024-05-18T18:11:15.257+0000] {processor.py:842} WARNING - No viable dags retrieved from /opt/airflow/dags/DE_DP_dag.py
[2024-05-18T18:11:15.281+0000] {processor.py:183} INFO - Processing /opt/airflow/dags/DE_DP_dag.py took 1.089 seconds
[2024-05-18T18:11:45.442+0000] {processor.py:161} INFO - Started process (PID=3081) to work on /opt/airflow/dags/DE_DP_dag.py
[2024-05-18T18:11:45.443+0000] {processor.py:830} INFO - Processing file /opt/airflow/dags/DE_DP_dag.py for tasks to queue
[2024-05-18T18:11:45.444+0000] {logging_mixin.py:188} INFO - [2024-05-18T18:11:45.444+0000] {dagbag.py:545} INFO - Filling up the DagBag from /opt/airflow/dags/DE_DP_dag.py
[2024-05-18T18:11:46.486+0000] {logging_mixin.py:188} INFO - [2024-05-18T18:11:46.479+0000] {dagbag.py:355} ERROR - Failed to import: /opt/airflow/dags/DE_DP_dag.py
Traceback (most recent call last):
  File "/home/airflow/.local/lib/python3.12/site-packages/airflow/models/dagbag.py", line 351, in parse
    loader.exec_module(new_module)
  File "<frozen importlib._bootstrap_external>", line 995, in exec_module
  File "<frozen importlib._bootstrap>", line 488, in _call_with_frames_removed
  File "/opt/airflow/dags/DE_DP_dag.py", line 130, in <module>
    dag_instance = my_text_classification_dag()
                   ^^^^^^^^^^^^^^^^^^^^^^^^^^^^
  File "/home/airflow/.local/lib/python3.12/site-packages/airflow/models/dag.py", line 4081, in factory
    f(**f_kwargs)
  File "/opt/airflow/dags/DE_DP_dag.py", line 119, in my_text_classification_dag
    train_scoring = train_accuracy_scoring_task(df_trained)
                                                ^^^^^^^^^^
NameError: name 'df_trained' is not defined. Did you mean: 'ds_trained'?
[2024-05-18T18:11:46.786+0000] {processor.py:842} WARNING - No viable dags retrieved from /opt/airflow/dags/DE_DP_dag.py
[2024-05-18T18:11:46.809+0000] {processor.py:183} INFO - Processing /opt/airflow/dags/DE_DP_dag.py took 1.373 seconds
[2024-05-18T18:12:16.987+0000] {processor.py:161} INFO - Started process (PID=3128) to work on /opt/airflow/dags/DE_DP_dag.py
[2024-05-18T18:12:16.988+0000] {processor.py:830} INFO - Processing file /opt/airflow/dags/DE_DP_dag.py for tasks to queue
[2024-05-18T18:12:16.990+0000] {logging_mixin.py:188} INFO - [2024-05-18T18:12:16.990+0000] {dagbag.py:545} INFO - Filling up the DagBag from /opt/airflow/dags/DE_DP_dag.py
[2024-05-18T18:12:18.040+0000] {logging_mixin.py:188} INFO - [2024-05-18T18:12:18.033+0000] {dagbag.py:355} ERROR - Failed to import: /opt/airflow/dags/DE_DP_dag.py
Traceback (most recent call last):
  File "/home/airflow/.local/lib/python3.12/site-packages/airflow/models/dagbag.py", line 351, in parse
    loader.exec_module(new_module)
  File "<frozen importlib._bootstrap_external>", line 995, in exec_module
  File "<frozen importlib._bootstrap>", line 488, in _call_with_frames_removed
  File "/opt/airflow/dags/DE_DP_dag.py", line 130, in <module>
    dag_instance = my_text_classification_dag()
                   ^^^^^^^^^^^^^^^^^^^^^^^^^^^^
  File "/home/airflow/.local/lib/python3.12/site-packages/airflow/models/dag.py", line 4081, in factory
    f(**f_kwargs)
  File "/opt/airflow/dags/DE_DP_dag.py", line 119, in my_text_classification_dag
    train_scoring = train_accuracy_scoring_task(df_trained)
                                                ^^^^^^^^^^
NameError: name 'df_trained' is not defined. Did you mean: 'ds_trained'?
[2024-05-18T18:12:18.042+0000] {processor.py:842} WARNING - No viable dags retrieved from /opt/airflow/dags/DE_DP_dag.py
[2024-05-18T18:12:18.066+0000] {processor.py:183} INFO - Processing /opt/airflow/dags/DE_DP_dag.py took 1.084 seconds
[2024-05-18T18:12:48.153+0000] {processor.py:161} INFO - Started process (PID=3175) to work on /opt/airflow/dags/DE_DP_dag.py
[2024-05-18T18:12:48.154+0000] {processor.py:830} INFO - Processing file /opt/airflow/dags/DE_DP_dag.py for tasks to queue
[2024-05-18T18:12:48.156+0000] {logging_mixin.py:188} INFO - [2024-05-18T18:12:48.155+0000] {dagbag.py:545} INFO - Filling up the DagBag from /opt/airflow/dags/DE_DP_dag.py
[2024-05-18T18:12:49.208+0000] {logging_mixin.py:188} INFO - [2024-05-18T18:12:49.201+0000] {dagbag.py:355} ERROR - Failed to import: /opt/airflow/dags/DE_DP_dag.py
Traceback (most recent call last):
  File "/home/airflow/.local/lib/python3.12/site-packages/airflow/models/dagbag.py", line 351, in parse
    loader.exec_module(new_module)
  File "<frozen importlib._bootstrap_external>", line 995, in exec_module
  File "<frozen importlib._bootstrap>", line 488, in _call_with_frames_removed
  File "/opt/airflow/dags/DE_DP_dag.py", line 130, in <module>
    dag_instance = my_text_classification_dag()
                   ^^^^^^^^^^^^^^^^^^^^^^^^^^^^
  File "/home/airflow/.local/lib/python3.12/site-packages/airflow/models/dag.py", line 4081, in factory
    f(**f_kwargs)
  File "/opt/airflow/dags/DE_DP_dag.py", line 119, in my_text_classification_dag
    train_scoring = train_accuracy_scoring_task(df_trained)
                                                ^^^^^^^^^^
NameError: name 'df_trained' is not defined. Did you mean: 'ds_trained'?
[2024-05-18T18:12:49.213+0000] {processor.py:842} WARNING - No viable dags retrieved from /opt/airflow/dags/DE_DP_dag.py
[2024-05-18T18:12:49.233+0000] {processor.py:183} INFO - Processing /opt/airflow/dags/DE_DP_dag.py took 1.086 seconds
[2024-05-18T18:13:19.389+0000] {processor.py:161} INFO - Started process (PID=3222) to work on /opt/airflow/dags/DE_DP_dag.py
[2024-05-18T18:13:19.390+0000] {processor.py:830} INFO - Processing file /opt/airflow/dags/DE_DP_dag.py for tasks to queue
[2024-05-18T18:13:19.392+0000] {logging_mixin.py:188} INFO - [2024-05-18T18:13:19.392+0000] {dagbag.py:545} INFO - Filling up the DagBag from /opt/airflow/dags/DE_DP_dag.py
[2024-05-18T18:13:20.437+0000] {logging_mixin.py:188} INFO - [2024-05-18T18:13:20.430+0000] {dagbag.py:355} ERROR - Failed to import: /opt/airflow/dags/DE_DP_dag.py
Traceback (most recent call last):
  File "/home/airflow/.local/lib/python3.12/site-packages/airflow/models/dagbag.py", line 351, in parse
    loader.exec_module(new_module)
  File "<frozen importlib._bootstrap_external>", line 995, in exec_module
  File "<frozen importlib._bootstrap>", line 488, in _call_with_frames_removed
  File "/opt/airflow/dags/DE_DP_dag.py", line 130, in <module>
    dag_instance = my_text_classification_dag()
                   ^^^^^^^^^^^^^^^^^^^^^^^^^^^^
  File "/home/airflow/.local/lib/python3.12/site-packages/airflow/models/dag.py", line 4081, in factory
    f(**f_kwargs)
  File "/opt/airflow/dags/DE_DP_dag.py", line 119, in my_text_classification_dag
    train_scoring = train_accuracy_scoring_task(df_trained)
                                                ^^^^^^^^^^
NameError: name 'df_trained' is not defined. Did you mean: 'ds_trained'?
[2024-05-18T18:13:20.439+0000] {processor.py:842} WARNING - No viable dags retrieved from /opt/airflow/dags/DE_DP_dag.py
[2024-05-18T18:13:20.465+0000] {processor.py:183} INFO - Processing /opt/airflow/dags/DE_DP_dag.py took 1.081 seconds
[2024-05-18T18:13:50.565+0000] {processor.py:161} INFO - Started process (PID=3269) to work on /opt/airflow/dags/DE_DP_dag.py
[2024-05-18T18:13:50.566+0000] {processor.py:830} INFO - Processing file /opt/airflow/dags/DE_DP_dag.py for tasks to queue
[2024-05-18T18:13:50.568+0000] {logging_mixin.py:188} INFO - [2024-05-18T18:13:50.568+0000] {dagbag.py:545} INFO - Filling up the DagBag from /opt/airflow/dags/DE_DP_dag.py
[2024-05-18T18:13:51.675+0000] {logging_mixin.py:188} INFO - [2024-05-18T18:13:51.668+0000] {dagbag.py:355} ERROR - Failed to import: /opt/airflow/dags/DE_DP_dag.py
Traceback (most recent call last):
  File "/home/airflow/.local/lib/python3.12/site-packages/airflow/models/dagbag.py", line 351, in parse
    loader.exec_module(new_module)
  File "<frozen importlib._bootstrap_external>", line 995, in exec_module
  File "<frozen importlib._bootstrap>", line 488, in _call_with_frames_removed
  File "/opt/airflow/dags/DE_DP_dag.py", line 130, in <module>
    dag_instance = my_text_classification_dag()
                   ^^^^^^^^^^^^^^^^^^^^^^^^^^^^
  File "/home/airflow/.local/lib/python3.12/site-packages/airflow/models/dag.py", line 4081, in factory
    f(**f_kwargs)
  File "/opt/airflow/dags/DE_DP_dag.py", line 119, in my_text_classification_dag
    train_scoring = train_accuracy_scoring_task(df_trained)
                                                ^^^^^^^^^^
NameError: name 'df_trained' is not defined. Did you mean: 'ds_trained'?
[2024-05-18T18:13:51.678+0000] {processor.py:842} WARNING - No viable dags retrieved from /opt/airflow/dags/DE_DP_dag.py
[2024-05-18T18:13:51.702+0000] {processor.py:183} INFO - Processing /opt/airflow/dags/DE_DP_dag.py took 1.143 seconds
[2024-05-18T18:14:21.804+0000] {processor.py:161} INFO - Started process (PID=3316) to work on /opt/airflow/dags/DE_DP_dag.py
[2024-05-18T18:14:21.805+0000] {processor.py:830} INFO - Processing file /opt/airflow/dags/DE_DP_dag.py for tasks to queue
[2024-05-18T18:14:21.808+0000] {logging_mixin.py:188} INFO - [2024-05-18T18:14:21.808+0000] {dagbag.py:545} INFO - Filling up the DagBag from /opt/airflow/dags/DE_DP_dag.py
[2024-05-18T18:14:22.945+0000] {logging_mixin.py:188} INFO - [2024-05-18T18:14:22.938+0000] {dagbag.py:355} ERROR - Failed to import: /opt/airflow/dags/DE_DP_dag.py
Traceback (most recent call last):
  File "/home/airflow/.local/lib/python3.12/site-packages/airflow/models/dagbag.py", line 351, in parse
    loader.exec_module(new_module)
  File "<frozen importlib._bootstrap_external>", line 995, in exec_module
  File "<frozen importlib._bootstrap>", line 488, in _call_with_frames_removed
  File "/opt/airflow/dags/DE_DP_dag.py", line 130, in <module>
    dag_instance = my_text_classification_dag()
                   ^^^^^^^^^^^^^^^^^^^^^^^^^^^^
  File "/home/airflow/.local/lib/python3.12/site-packages/airflow/models/dag.py", line 4081, in factory
    f(**f_kwargs)
  File "/opt/airflow/dags/DE_DP_dag.py", line 119, in my_text_classification_dag
    train_scoring = train_accuracy_scoring_task(df_trained)
                                                ^^^^^^^^^^
NameError: name 'df_trained' is not defined. Did you mean: 'ds_trained'?
[2024-05-18T18:14:22.948+0000] {processor.py:842} WARNING - No viable dags retrieved from /opt/airflow/dags/DE_DP_dag.py
[2024-05-18T18:14:22.972+0000] {processor.py:183} INFO - Processing /opt/airflow/dags/DE_DP_dag.py took 1.177 seconds
[2024-05-18T18:14:53.254+0000] {processor.py:161} INFO - Started process (PID=3363) to work on /opt/airflow/dags/DE_DP_dag.py
[2024-05-18T18:14:53.255+0000] {processor.py:830} INFO - Processing file /opt/airflow/dags/DE_DP_dag.py for tasks to queue
[2024-05-18T18:14:53.257+0000] {logging_mixin.py:188} INFO - [2024-05-18T18:14:53.256+0000] {dagbag.py:545} INFO - Filling up the DagBag from /opt/airflow/dags/DE_DP_dag.py
[2024-05-18T18:14:54.313+0000] {logging_mixin.py:188} INFO - [2024-05-18T18:14:54.303+0000] {dagbag.py:355} ERROR - Failed to import: /opt/airflow/dags/DE_DP_dag.py
Traceback (most recent call last):
  File "/home/airflow/.local/lib/python3.12/site-packages/airflow/models/dagbag.py", line 351, in parse
    loader.exec_module(new_module)
  File "<frozen importlib._bootstrap_external>", line 995, in exec_module
  File "<frozen importlib._bootstrap>", line 488, in _call_with_frames_removed
  File "/opt/airflow/dags/DE_DP_dag.py", line 130, in <module>
    dag_instance = my_text_classification_dag()
                   ^^^^^^^^^^^^^^^^^^^^^^^^^^^^
  File "/home/airflow/.local/lib/python3.12/site-packages/airflow/models/dag.py", line 4081, in factory
    f(**f_kwargs)
  File "/opt/airflow/dags/DE_DP_dag.py", line 119, in my_text_classification_dag
    train_scoring = train_accuracy_scoring_task(df_trained)
                                                ^^^^^^^^^^
NameError: name 'df_trained' is not defined. Did you mean: 'ds_trained'?
[2024-05-18T18:14:54.316+0000] {processor.py:842} WARNING - No viable dags retrieved from /opt/airflow/dags/DE_DP_dag.py
[2024-05-18T18:14:54.340+0000] {processor.py:183} INFO - Processing /opt/airflow/dags/DE_DP_dag.py took 1.092 seconds
[2024-05-18T18:15:24.423+0000] {processor.py:161} INFO - Started process (PID=3410) to work on /opt/airflow/dags/DE_DP_dag.py
[2024-05-18T18:15:24.424+0000] {processor.py:830} INFO - Processing file /opt/airflow/dags/DE_DP_dag.py for tasks to queue
[2024-05-18T18:15:24.426+0000] {logging_mixin.py:188} INFO - [2024-05-18T18:15:24.426+0000] {dagbag.py:545} INFO - Filling up the DagBag from /opt/airflow/dags/DE_DP_dag.py
[2024-05-18T18:15:25.467+0000] {logging_mixin.py:188} INFO - [2024-05-18T18:15:25.461+0000] {dagbag.py:355} ERROR - Failed to import: /opt/airflow/dags/DE_DP_dag.py
Traceback (most recent call last):
  File "/home/airflow/.local/lib/python3.12/site-packages/airflow/models/dagbag.py", line 351, in parse
    loader.exec_module(new_module)
  File "<frozen importlib._bootstrap_external>", line 995, in exec_module
  File "<frozen importlib._bootstrap>", line 488, in _call_with_frames_removed
  File "/opt/airflow/dags/DE_DP_dag.py", line 130, in <module>
    dag_instance = my_text_classification_dag()
                   ^^^^^^^^^^^^^^^^^^^^^^^^^^^^
  File "/home/airflow/.local/lib/python3.12/site-packages/airflow/models/dag.py", line 4081, in factory
    f(**f_kwargs)
  File "/opt/airflow/dags/DE_DP_dag.py", line 119, in my_text_classification_dag
    train_scoring = train_accuracy_scoring_task(df_trained)
                                                ^^^^^^^^^^
NameError: name 'df_trained' is not defined. Did you mean: 'ds_trained'?
[2024-05-18T18:15:25.469+0000] {processor.py:842} WARNING - No viable dags retrieved from /opt/airflow/dags/DE_DP_dag.py
[2024-05-18T18:15:25.488+0000] {processor.py:183} INFO - Processing /opt/airflow/dags/DE_DP_dag.py took 1.071 seconds
[2024-05-18T18:15:55.684+0000] {processor.py:161} INFO - Started process (PID=3457) to work on /opt/airflow/dags/DE_DP_dag.py
[2024-05-18T18:15:55.685+0000] {processor.py:830} INFO - Processing file /opt/airflow/dags/DE_DP_dag.py for tasks to queue
[2024-05-18T18:15:55.687+0000] {logging_mixin.py:188} INFO - [2024-05-18T18:15:55.687+0000] {dagbag.py:545} INFO - Filling up the DagBag from /opt/airflow/dags/DE_DP_dag.py
[2024-05-18T18:15:56.748+0000] {logging_mixin.py:188} INFO - [2024-05-18T18:15:56.741+0000] {dagbag.py:355} ERROR - Failed to import: /opt/airflow/dags/DE_DP_dag.py
Traceback (most recent call last):
  File "/home/airflow/.local/lib/python3.12/site-packages/airflow/models/dagbag.py", line 351, in parse
    loader.exec_module(new_module)
  File "<frozen importlib._bootstrap_external>", line 995, in exec_module
  File "<frozen importlib._bootstrap>", line 488, in _call_with_frames_removed
  File "/opt/airflow/dags/DE_DP_dag.py", line 130, in <module>
    dag_instance = my_text_classification_dag()
                   ^^^^^^^^^^^^^^^^^^^^^^^^^^^^
  File "/home/airflow/.local/lib/python3.12/site-packages/airflow/models/dag.py", line 4081, in factory
    f(**f_kwargs)
  File "/opt/airflow/dags/DE_DP_dag.py", line 119, in my_text_classification_dag
    train_scoring = train_accuracy_scoring_task(df_trained)
                                                ^^^^^^^^^^
NameError: name 'df_trained' is not defined. Did you mean: 'ds_trained'?
[2024-05-18T18:15:56.750+0000] {processor.py:842} WARNING - No viable dags retrieved from /opt/airflow/dags/DE_DP_dag.py
[2024-05-18T18:15:56.774+0000] {processor.py:183} INFO - Processing /opt/airflow/dags/DE_DP_dag.py took 1.095 seconds
[2024-05-18T18:16:26.859+0000] {processor.py:161} INFO - Started process (PID=3504) to work on /opt/airflow/dags/DE_DP_dag.py
[2024-05-18T18:16:26.861+0000] {processor.py:830} INFO - Processing file /opt/airflow/dags/DE_DP_dag.py for tasks to queue
[2024-05-18T18:16:26.862+0000] {logging_mixin.py:188} INFO - [2024-05-18T18:16:26.862+0000] {dagbag.py:545} INFO - Filling up the DagBag from /opt/airflow/dags/DE_DP_dag.py
[2024-05-18T18:16:27.936+0000] {logging_mixin.py:188} INFO - [2024-05-18T18:16:27.929+0000] {dagbag.py:355} ERROR - Failed to import: /opt/airflow/dags/DE_DP_dag.py
Traceback (most recent call last):
  File "/home/airflow/.local/lib/python3.12/site-packages/airflow/models/dagbag.py", line 351, in parse
    loader.exec_module(new_module)
  File "<frozen importlib._bootstrap_external>", line 995, in exec_module
  File "<frozen importlib._bootstrap>", line 488, in _call_with_frames_removed
  File "/opt/airflow/dags/DE_DP_dag.py", line 130, in <module>
    dag_instance = my_text_classification_dag()
                   ^^^^^^^^^^^^^^^^^^^^^^^^^^^^
  File "/home/airflow/.local/lib/python3.12/site-packages/airflow/models/dag.py", line 4081, in factory
    f(**f_kwargs)
  File "/opt/airflow/dags/DE_DP_dag.py", line 119, in my_text_classification_dag
    train_scoring = train_accuracy_scoring_task(df_trained)
                                                ^^^^^^^^^^
NameError: name 'df_trained' is not defined. Did you mean: 'ds_trained'?
[2024-05-18T18:16:27.939+0000] {processor.py:842} WARNING - No viable dags retrieved from /opt/airflow/dags/DE_DP_dag.py
[2024-05-18T18:16:27.961+0000] {processor.py:183} INFO - Processing /opt/airflow/dags/DE_DP_dag.py took 1.107 seconds
[2024-05-18T18:16:58.155+0000] {processor.py:161} INFO - Started process (PID=3616) to work on /opt/airflow/dags/DE_DP_dag.py
[2024-05-18T18:16:58.158+0000] {processor.py:830} INFO - Processing file /opt/airflow/dags/DE_DP_dag.py for tasks to queue
[2024-05-18T18:16:58.162+0000] {logging_mixin.py:188} INFO - [2024-05-18T18:16:58.161+0000] {dagbag.py:545} INFO - Filling up the DagBag from /opt/airflow/dags/DE_DP_dag.py
[2024-05-18T18:17:01.266+0000] {logging_mixin.py:188} INFO - [2024-05-18T18:17:01.260+0000] {dagbag.py:355} ERROR - Failed to import: /opt/airflow/dags/DE_DP_dag.py
Traceback (most recent call last):
  File "/home/airflow/.local/lib/python3.12/site-packages/airflow/models/dagbag.py", line 351, in parse
    loader.exec_module(new_module)
  File "<frozen importlib._bootstrap_external>", line 995, in exec_module
  File "<frozen importlib._bootstrap>", line 488, in _call_with_frames_removed
  File "/opt/airflow/dags/DE_DP_dag.py", line 130, in <module>
    dag_instance = my_text_classification_dag()
                   ^^^^^^^^^^^^^^^^^^^^^^^^^^^^
  File "/home/airflow/.local/lib/python3.12/site-packages/airflow/models/dag.py", line 4081, in factory
    f(**f_kwargs)
  File "/opt/airflow/dags/DE_DP_dag.py", line 119, in my_text_classification_dag
    train_scoring = train_accuracy_scoring_task(df_trained)
                                                ^^^^^^^^^^
NameError: name 'df_trained' is not defined. Did you mean: 'ds_trained'?
[2024-05-18T18:17:01.268+0000] {processor.py:842} WARNING - No viable dags retrieved from /opt/airflow/dags/DE_DP_dag.py
[2024-05-18T18:17:01.295+0000] {processor.py:183} INFO - Processing /opt/airflow/dags/DE_DP_dag.py took 3.163 seconds
